<sdf version='1.6'>
  <world name='default'>
    <light name='sun' type='directional'>
      <cast_shadows>1</cast_shadows>
      <pose frame=''>0 0 10 0 -0 0</pose>
      <diffuse>0.8 0.8 0.8 1</diffuse>
      <specular>0.1 0.1 0.1 1</specular>
      <attenuation>
        <range>1000</range>
        <constant>0.9</constant>
        <linear>0.01</linear>
        <quadratic>0.001</quadratic>
      </attenuation>
      <direction>-0.5 0.5 -1</direction>
    </light>
    <model name='ground_plane'>
      <static>1</static>
      <link name='link'>
        <collision name='collision'>
          <geometry>
            <plane>
              <normal>0 0 1</normal>
              <size>100 100</size>
            </plane>
          </geometry>
          <surface>
            <friction>
              <ode>
                <mu>100</mu>
                <mu2>50</mu2>
              </ode>
              <torsional>
                <ode/>
              </torsional>
            </friction>
            <contact>
              <ode/>
            </contact>
            <bounce/>
          </surface>
          <max_contacts>10</max_contacts>
        </collision>
        <visual name='visual'>
          <cast_shadows>0</cast_shadows>
          <geometry>
            <plane>
              <normal>0 0 1</normal>
              <size>100 100</size>
            </plane>
          </geometry>
          <material>
            <script>
              <uri>file://media/materials/scripts/gazebo.material</uri>
              <name>Gazebo/Grey</name>
            </script>
          </material>
        </visual>
        <self_collide>0</self_collide>
        <kinematic>0</kinematic>
        <gravity>1</gravity>
      </link>
    </model>
    <gravity>0 0 -9.8</gravity>
    <magnetic_field>6e-06 2.3e-05 -4.2e-05</magnetic_field>
    <atmosphere type='adiabatic'/>
    <physics name='default_physics' default='0' type='ode'>
      <max_step_size>0.001</max_step_size>
      <real_time_factor>1</real_time_factor>
      <real_time_update_rate>1000</real_time_update_rate>
    </physics>
    <scene>
      <ambient>0.4 0.4 0.4 1</ambient>
      <background>0.7 0.7 0.7 1</background>
      <shadows>1</shadows>
    </scene>
    <spherical_coordinates>
      <surface_model>EARTH_WGS84</surface_model>
      <latitude_deg>0</latitude_deg>
      <longitude_deg>0</longitude_deg>
      <elevation>0</elevation>
      <heading_deg>0</heading_deg>
    </spherical_coordinates>
    <state world_name='default'>
      <sim_time>1398 41000000</sim_time>
      <real_time>86 672210</real_time>
      <wall_time>1589136509 872481873</wall_time>
      <iterations>39859</iterations>
      <model name='bookshelf'>
        <pose frame=''>3.32468 -4.28542 0 0 -0 0</pose>
        <scale>1 1 1</scale>
        <link name='link'>
          <pose frame=''>3.32468 -4.28542 0 0 -0 0</pose>
          <velocity>0 0 0 0 -0 0</velocity>
          <acceleration>0 0 0 0 -0 0</acceleration>
          <wrench>0 0 0 0 -0 0</wrench>
        </link>
      </model>
      <model name='c_world'>
        <pose frame=''>3.3837 -3.24072 0 0 -0 0</pose>
        <scale>1 1 1</scale>
        <link name='Wall_32'>
          <pose frame=''>3.3837 -7.16572 0 0 -0 0</pose>
          <velocity>0 0 0 0 -0 0</velocity>
          <acceleration>0 0 0 0 -0 0</acceleration>
          <wrench>0 0 0 0 -0 0</wrench>
        </link>
        <link name='Wall_38'>
          <pose frame=''>6.8837 0.684278 0 0 -0 3.14159</pose>
          <velocity>0 0 0 0 -0 0</velocity>
          <acceleration>0 0 0 0 -0 0</acceleration>
          <wrench>0 0 0 0 -0 0</wrench>
        </link>
        <link name='Wall_39'>
          <pose frame=''>5.4587 -1.74072 0 0 0 -1.5708</pose>
          <velocity>0 0 0 0 -0 0</velocity>
          <acceleration>0 0 0 0 -0 0</acceleration>
          <wrench>0 0 0 0 -0 0</wrench>
        </link>
        <link name='Wall_41'>
          <pose frame=''>1.3087 -1.74072 0 0 -0 1.5708</pose>
          <velocity>0 0 0 0 -0 0</velocity>
          <acceleration>0 0 0 0 -0 0</acceleration>
          <wrench>0 0 0 0 -0 0</wrench>
        </link>
        <link name='Wall_42'>
          <pose frame=''>-0.116304 0.684278 0 0 -0 3.14159</pose>
          <velocity>0 0 0 0 -0 0</velocity>
          <acceleration>0 0 0 0 -0 0</acceleration>
          <wrench>0 0 0 0 -0 0</wrench>
        </link>
        <link name='Wall_44'>
          <pose frame=''>3.3837 -4.16572 0 0 -0 3.14159</pose>
          <velocity>0 0 0 0 -0 0</velocity>
          <acceleration>0 0 0 0 -0 0</acceleration>
          <wrench>0 0 0 0 -0 0</wrench>
        </link>
        <link name='Wall_46'>
          <pose frame=''>-1.5413 -3.24072 0 0 0 -1.5708</pose>
          <velocity>0 0 0 0 -0 0</velocity>
          <acceleration>0 0 0 0 -0 0</acceleration>
          <wrench>0 0 0 0 -0 0</wrench>
        </link>
        <link name='Wall_48'>
          <pose frame=''>8.3087 -3.24072 0 0 0 -1.5708</pose>
          <velocity>0 0 0 0 -0 0</velocity>
          <acceleration>0 0 0 0 -0 0</acceleration>
          <wrench>0 0 0 0 -0 0</wrench>
        </link>
      </model>
      <model name='cabinet'>
        <pose frame=''>0.941746 0.365453 0 0 -0 0</pose>
        <scale>1 1 1</scale>
        <link name='cabinet_bottom_plate'>
          <pose frame=''>0.941746 0.365453 0 0 -0 0</pose>
          <velocity>0 0 0 0 -0 0</velocity>
          <acceleration>0 0 0 0 -0 0</acceleration>
          <wrench>0 0 0 0 -0 0</wrench>
        </link>
      </model>
      <model name='ground_plane'>
        <pose frame=''>0 0 0 0 -0 0</pose>
        <scale>1 1 1</scale>
        <link name='link'>
          <pose frame=''>0 0 0 0 -0 0</pose>
          <velocity>0 0 0 0 -0 0</velocity>
          <acceleration>0 0 0 0 -0 0</acceleration>
          <wrench>0 0 0 0 -0 0</wrench>
        </link>
      </model>
      <model name='mars_rover'>
        <pose frame=''>7.24994 -6.23589 0 0 -0 0</pose>
        <scale>1 1 1</scale>
        <link name='link'>
          <pose frame=''>7.24994 -6.23589 0 0 -0 0</pose>
          <velocity>0 0 0 0 -0 0</velocity>
          <acceleration>0 0 0 0 -0 0</acceleration>
          <wrench>0 0 0 0 -0 0</wrench>
        </link>
      </model>
      <model name='mobile_base'>
        <pose frame=''>0.064326 -0.7759 -0.000248 0.000771 -0.014416 -2.92538</pose>
        <scale>1 1 1</scale>
        <link name='base_footprint'>
          <pose frame=''>0.064326 -0.7759 -0.000248 0.000771 -0.014416 -2.92538</pose>
          <velocity>0.000283 0.000143 -9.9e-05 0.000755 -0.001683 8.1e-05</velocity>
          <acceleration>-0.011151 -0.004343 0.148936 0.575862 -1.04698 0.180054</acceleration>
          <wrench>-0.052379 -0.0204 0.699595 0 -0 0</wrench>
        </link>
        <link name='wheel_left_link'>
          <pose frame=''>0.089491 -0.888086 0.035181 -1.56935 -1.01407 -2.9266</pose>
          <velocity>0.000233 0.000119 -0.000141 0.000755 -0.001683 8.1e-05</velocity>
          <acceleration>-0.123621 -0.075049 1.25531 -0.076729 1.08532 0.051644</acceleration>
          <wrench>-0.001236 -0.00075 0.012553 0 -0 0</wrench>
        </link>
        <link name='wheel_right_link'>
          <pose frame=''>0.040145 -0.663441 0.034984 -1.56882 -1.17381 -2.92719</pose>
          <velocity>0.000215 0.000115 -5.4e-05 0.000755 -0.001683 8.1e-05</velocity>
          <acceleration>-0.119929 -0.077297 1.10284 0.030339 0.996726 0.052899</acceleration>
          <wrench>-0.001199 -0.000773 0.011028 0 -0 0</wrench>
        </link>
      </model>
      <model name='warehouse_robot'>
        <pose frame=''>-0.961337 -6.5405 0 0 -0 0</pose>
        <scale>1 1 1</scale>
        <link name='link'>
          <pose frame=''>-0.961337 -6.5405 0 0 -0 0</pose>
          <velocity>0 0 0 0 -0 0</velocity>
          <acceleration>0 0 0 0 -0 0</acceleration>
          <wrench>0 0 0 0 -0 0</wrench>
        </link>
      </model>
      <model name='youbot'>
        <pose frame=''>6.08239 0.248622 0.083974 1.1e-05 1.8e-05 -0.001083</pose>
        <scale>1 1 1</scale>
        <link name='arm_link_0'>
          <pose frame=''>6.22539 0.248467 0.129969 1.6e-05 2e-05 -0.001083</pose>
          <velocity>2.6e-05 -2.4e-05 -0.003363 -0.000972 -0.00019 -0.001422</velocity>
          <acceleration>0.021156 0.0251 -3.67329 -0.876575 -0.170484 -2.69599</acceleration>
          <wrench>0.017876 0.02121 -3.10393 0 -0 0</wrench>
        </link>
        <link name='arm_link_1'>
          <pose frame=''>6.24939 0.24844 0.225968 -2.4e-05 -2.7e-05 2.96175</pose>
          <velocity>3.1e-05 -0.000105 -0.003355 -0.003646 -0.000453 -0.003145</velocity>
          <acceleration>0.080957 -0.09055 -3.69115 2.38941 -0.61863 -0.02711</acceleration>
          <wrench>0.195268 -0.218408 -8.90305 0 -0 0</wrench>
        </link>
        <link name='arm_link_2'>
          <pose frame=''>6.21692 0.254342 0.244968 -9e-05 -1.13448 2.96181</pose>
          <velocity>5e-05 8.2e-05 -0.003247 -0.006509 -0.004272 0.003336</velocity>
          <acceleration>-0.252047 0.279462 -3.72872 2.86918 -0.986234 0.773743</acceleration>
          <wrench>-0.291114 0.322779 -4.30668 0 -0 0</wrench>
        </link>
        <link name='arm_link_3'>
          <pose frame=''>6.35514 0.229213 0.310454 0.000451 1.4137 2.96218</pose>
          <velocity>-0.000418 0.000257 -0.000654 0.005206 0.016732 0.00331</velocity>
          <acceleration>0.185181 -0.003718 -1.44055 -2.5431 -1.35843 -2.42358</acceleration>
          <wrench>0.172959 -0.003472 -1.34548 0 -0 0</wrench>
        </link>
        <link name='arm_link_4'>
          <pose frame=''>6.22395 0.253066 0.331573 0.000105 -0.375315 2.9617</pose>
          <velocity>-0.000218 -0.000225 0.002367 0.004761 0.00436 0.004451</velocity>
          <acceleration>-0.213546 -0.458475 -0.769438 -2.32419 -1.38462 0.221691</acceleration>
          <wrench>-0.18728 -0.402082 -0.674797 0 -0 0</wrench>
        </link>
        <link name='arm_link_5'>
          <pose frame=''>6.27267 0.244219 0.451791 -0.111083 0.359247 -0.486838</pose>
          <velocity>0.000337 -0.000967 0.002338 -0.003925 0.00815 0.002546</velocity>
          <acceleration>-0.814248 -1.63999 0.02068 -1.16818 -1.27215 1.26692</acceleration>
          <wrench>-0.204376 -0.411636 0.005191 0 -0 0</wrench>
        </link>
        <link name='base_footprint'>
          <pose frame=''>6.08239 0.248622 0.083974 1.1e-05 1.8e-05 -0.001083</pose>
          <velocity>2.6e-05 -2e-05 -0.0035 0.000358 -8e-06 -0.000127</velocity>
          <acceleration>-0.014596 0.053535 -3.74899 0.406042 0.601809 -0.071253</acceleration>
          <wrench>-0.00146 0.005354 -0.374899 0 -0 0</wrench>
        </link>
        <link name='base_laser_front_link'>
          <pose frame=''>6.38239 0.248298 0.053968 1e-05 1.8e-05 -0.001083</pose>
          <velocity>2.5e-05 -5e-05 -0.003506 0.000363 -2e-06 -0.000111</velocity>
          <acceleration>-0.001868 0.022502 -3.94045 0.410717 0.609122 -0.038013</acceleration>
          <wrench>-0.000299 0.0036 -0.630471 0 -0 0</wrench>
        </link>
        <link name='base_link'>
          <pose frame=''>6.08239 0.248622 0.083974 1.1e-05 1.8e-05 -0.001083</pose>
          <velocity>2.5e-05 -2.1e-05 -0.003499 0.000357 -1e-05 -0.000128</velocity>
          <acceleration>0.015559 0.03325 -3.74817 0.404302 0.600686 -0.070623</acceleration>
          <wrench>0.342288 0.731505 -82.4596 0 -0 0</wrench>
        </link>
        <link name='caster_link_bl'>
          <pose frame=''>5.85456 0.406869 0.049994 1.1e-05 1.8e-05 -0.000926</pose>
          <velocity>4.7e-05 1.8e-05 -0.007303 0.000284 -2e-06 -4.2e-05</velocity>
          <acceleration>0.01079 0.061191 -7.5982 0.327084 0.609432 -0.016246</acceleration>
          <wrench>0.001079 0.006119 -0.75982 0 -0 0</wrench>
        </link>
        <link name='caster_link_br'>
          <pose frame=''>5.85422 0.090869 0.049999 1.1e-05 1.8e-05 -0.000905</pose>
          <velocity>3e-06 2e-05 0.000853 0.000464 1.8e-05 -4.7e-05</velocity>
          <acceleration>-0.014185 0.063112 0.521308 0.507661 0.630761 -0.021686</acceleration>
          <wrench>-0.001419 0.006311 0.052131 0 -0 0</wrench>
        </link>
        <link name='caster_link_fl'>
          <pose frame=''>6.31056 0.406375 0.049999 1.1e-05 1.8e-05 -0.000871</pose>
          <velocity>4.6e-05 -4.5e-05 0.000929 0.000481 -5e-06 -4.7e-05</velocity>
          <acceleration>0.010592 0.025555 0.541544 0.52778 0.608903 -0.022524</acceleration>
          <wrench>0.001059 0.002555 0.054154 0 -0 0</wrench>
        </link>
        <link name='caster_link_fr'>
          <pose frame=''>6.31022 0.090376 0.049992 1.1e-05 1.8e-05 -0.00085</pose>
          <velocity>6e-06 -4.3e-05 -0.009971 0.0003 1.8e-05 -4.2e-05</velocity>
          <acceleration>-0.011337 0.026875 -10.4405 0.600149 0.631619 -0.02499</acceleration>
          <wrench>-0.001134 0.002688 -1.04405 0 -0 0</wrench>
        </link>
        <link name='gripper_finger_link_l'>
          <pose frame=''>6.30097 0.256943 0.491159 0.111084 -0.359247 2.65476</pose>
          <velocity>0.002477 0.003175 0.001623 -0.003412 0.006245 0.000405</velocity>
          <acceleration>0.296054 0.727356 -0.252277 0.703132 -1.44476 -0.565339</acceleration>
          <wrench>0.002961 0.007274 -0.002523 0 -0 0</wrench>
        </link>
        <link name='gripper_finger_link_r'>
          <pose frame=''>6.28913 0.232286 0.494013 -0.111084 0.359247 -0.486839</pose>
          <velocity>0.002506 0.003182 0.001775 -0.003324 0.006186 0.000367</velocity>
          <acceleration>0.277807 0.730614 -0.297815 0.783437 -1.49635 -0.600044</acceleration>
          <wrench>0.002778 0.007306 -0.002978 0 -0 0</wrench>
        </link>
        <link name='gripper_palm_link'>
          <pose frame=''>6.27267 0.244219 0.451791 -0.111084 0.359247 -0.486839</pose>
          <velocity>0.000233 -0.001141 0.002341 -0.003453 0.006272 0.000423</velocity>
          <acceleration>-0.892925 -1.79272 0.014573 0.6661 -1.41982 -0.549342</acceleration>
          <wrench>-0.089292 -0.179272 0.001457 0 -0 0</wrench>
        </link>
        <link name='plate_link'>
          <pose frame=''>5.92339 0.248794 0.129976 1.1e-05 1.8e-05 -0.001083</pose>
          <velocity>2.5e-05 -1.8e-05 -0.0035 0.000353 -1.5e-05 -0.000129</velocity>
          <acceleration>0.043823 0.025306 -3.65021 0.399803 0.597691 -0.070059</acceleration>
          <wrench>0.043823 0.025306 -3.65021 0 -0 0</wrench>
        </link>
        <link name='wheel_link_bl'>
          <pose frame=''>5.85456 0.406869 0.049993 1.1e-05 2.1e-05 -0.000926</pose>
          <velocity>4.6e-05 1.9e-05 -0.007027 0.000236 -0.000231 -3.8e-05</velocity>
          <acceleration>0.009599 0.062678 -7.31145 0.27664 -0.013243 -0.011997</acceleration>
          <wrench>0.00384 0.025071 -2.92458 0 -0 0</wrench>
        </link>
        <link name='wheel_link_br'>
          <pose frame=''>5.85422 0.090869 0.049998 1.1e-05 2.1e-05 -0.000905</pose>
          <velocity>3e-06 2.2e-05 0.000631 0.000529 -0.000217 -5.2e-05</velocity>
          <acceleration>-0.015549 0.064603 0.312901 0.569124 5.4e-05 -0.026426</acceleration>
          <wrench>-0.00622 0.025841 0.12516 0 -0 0</wrench>
        </link>
        <link name='wheel_link_fl'>
          <pose frame=''>6.31056 0.406375 0.049998 1.1e-05 2.1e-05 -0.000871</pose>
          <velocity>4.6e-05 -4.3e-05 0.000709 0.000545 -0.000216 -5.2e-05</velocity>
          <acceleration>0.009402 0.02679 0.323433 0.591977 0.001024 -0.027475</acceleration>
          <wrench>0.003761 0.010716 0.129373 0 -0 0</wrench>
        </link>
        <link name='wheel_link_fr'>
          <pose frame=''>6.31022 0.090376 0.049991 1.1e-05 2.1e-05 -0.00085</pose>
          <velocity>6e-06 -4.2e-05 -0.00957 0.00025 -0.000229 -3.8e-05</velocity>
          <acceleration>-0.012746 0.028089 -10.0353 0.723225 0.008448 -0.034764</acceleration>
          <wrench>-0.005098 0.011236 -4.01412 0 -0 0</wrench>
        </link>
      </model>
      <light name='sun'>
        <pose frame=''>0 0 10 0 -0 0</pose>
      </light>
    </state>
    <model name='c_world'>
      <pose frame=''>-11.6404 3.12249 0 0 -0 0</pose>
      <link name='Wall_32'>
        <pose frame=''>0 -3.925 0 0 -0 0</pose>
        <visual name='Wall_32_Visual_0'>
          <pose frame=''>-4.49849 0 1.25 0 -0 0</pose>
          <geometry>
            <box>
              <size>1.00301 0.15 2.5</size>
            </box>
          </geometry>
          <material>
            <script>
              <uri>file://media/materials/scripts/gazebo.material</uri>
              <name>Gazebo/Bricks</name>
            </script>
            <ambient>1 1 1 1</ambient>
          </material>
        </visual>
        <collision name='Wall_32_Collision_0'>
          <geometry>
            <box>
              <size>1.00301 0.15 2.5</size>
            </box>
          </geometry>
          <pose frame=''>-4.49849 0 1.25 0 -0 0</pose>
          <max_contacts>10</max_contacts>
          <surface>
            <contact>
              <ode/>
            </contact>
            <bounce/>
            <friction>
              <torsional>
                <ode/>
              </torsional>
              <ode/>
            </friction>
          </surface>
        </collision>
        <visual name='Wall_32_Visual_1'>
          <pose frame=''>0.501507 0 0.25 0 -0 0</pose>
          <geometry>
            <box>
              <size>8.99699 0.15 0.5</size>
            </box>
          </geometry>
          <material>
            <script>
              <uri>file://media/materials/scripts/gazebo.material</uri>
              <name>Gazebo/Bricks</name>
            </script>
            <ambient>1 1 1 1</ambient>
          </material>
        </visual>
        <collision name='Wall_32_Collision_1'>
          <geometry>
            <box>
              <size>8.99699 0.15 0.5</size>
            </box>
          </geometry>
          <pose frame=''>0.501507 0 0.25 0 -0 0</pose>
          <max_contacts>10</max_contacts>
          <surface>
            <contact>
              <ode/>
            </contact>
            <bounce/>
            <friction>
              <torsional>
                <ode/>
              </torsional>
              <ode/>
            </friction>
          </surface>
        </collision>
        <visual name='Wall_32_Visual_2'>
          <pose frame=''>-0.002914 0 1.5 0 -0 0</pose>
          <geometry>
            <box>
              <size>6.38814 0.15 2</size>
            </box>
          </geometry>
          <material>
            <script>
              <uri>file://media/materials/scripts/gazebo.material</uri>
              <name>Gazebo/Bricks</name>
            </script>
            <ambient>1 1 1 1</ambient>
          </material>
        </visual>
        <collision name='Wall_32_Collision_2'>
          <geometry>
            <box>
              <size>6.38814 0.15 2</size>
            </box>
          </geometry>
          <pose frame=''>-0.002914 0 1.5 0 -0 0</pose>
          <max_contacts>10</max_contacts>
          <surface>
            <contact>
              <ode/>
            </contact>
            <bounce/>
            <friction>
              <torsional>
                <ode/>
              </torsional>
              <ode/>
            </friction>
          </surface>
        </collision>
        <visual name='Wall_32_Visual_3'>
          <pose frame=''>4.49558 0 1.5 0 -0 0</pose>
          <geometry>
            <box>
              <size>1.00884 0.15 2</size>
            </box>
          </geometry>
          <material>
            <script>
              <uri>file://media/materials/scripts/gazebo.material</uri>
              <name>Gazebo/Bricks</name>
            </script>
            <ambient>1 1 1 1</ambient>
          </material>
        </visual>
        <collision name='Wall_32_Collision_3'>
          <geometry>
            <box>
              <size>1.00884 0.15 2</size>
            </box>
          </geometry>
          <pose frame=''>4.49558 0 1.5 0 -0 0</pose>
          <max_contacts>10</max_contacts>
          <surface>
            <contact>
              <ode/>
            </contact>
            <bounce/>
            <friction>
              <torsional>
                <ode/>
              </torsional>
              <ode/>
            </friction>
          </surface>
        </collision>
        <visual name='Wall_32_Visual_4'>
          <pose frame=''>-3.59699 0 1.9 0 -0 0</pose>
          <geometry>
            <box>
              <size>0.8 0.15 1.2</size>
            </box>
          </geometry>
          <material>
            <script>
              <uri>file://media/materials/scripts/gazebo.material</uri>
              <name>Gazebo/Bricks</name>
            </script>
            <ambient>1 1 1 1</ambient>
          </material>
        </visual>
        <collision name='Wall_32_Collision_4'>
          <geometry>
            <box>
              <size>0.8 0.15 1.2</size>
            </box>
          </geometry>
          <pose frame=''>-3.59699 0 1.9 0 -0 0</pose>
          <max_contacts>10</max_contacts>
          <surface>
            <contact>
              <ode/>
            </contact>
            <bounce/>
            <friction>
              <torsional>
                <ode/>
              </torsional>
              <ode/>
            </friction>
          </surface>
        </collision>
        <visual name='Wall_32_Visual_5'>
          <pose frame=''>3.59116 0 1.9 0 -0 0</pose>
          <geometry>
            <box>
              <size>0.8 0.15 1.2</size>
            </box>
          </geometry>
          <material>
            <script>
              <uri>file://media/materials/scripts/gazebo.material</uri>
              <name>Gazebo/Bricks</name>
            </script>
            <ambient>1 1 1 1</ambient>
          </material>
        </visual>
        <collision name='Wall_32_Collision_5'>
          <geometry>
            <box>
              <size>0.8 0.15 1.2</size>
            </box>
          </geometry>
          <pose frame=''>3.59116 0 1.9 0 -0 0</pose>
          <max_contacts>10</max_contacts>
          <surface>
            <contact>
              <ode/>
            </contact>
            <bounce/>
            <friction>
              <torsional>
                <ode/>
              </torsional>
              <ode/>
            </friction>
          </surface>
        </collision>
        <self_collide>0</self_collide>
        <kinematic>0</kinematic>
        <gravity>1</gravity>
      </link>
      <link name='Wall_38'>
        <pose frame=''>3.5 3.925 0 0 -0 3.14159</pose>
        <visual name='Wall_38_Visual_0'>
          <pose frame=''>-0.932339 0 1.25 0 -0 0</pose>
          <geometry>
            <box>
              <size>1.13532 0.15 2.5</size>
            </box>
          </geometry>
          <material>
            <script>
              <uri>file://media/materials/scripts/gazebo.material</uri>
              <name>Gazebo/Bricks</name>
            </script>
            <ambient>0.921569 0.807843 0.615686 1</ambient>
          </material>
        </visual>
        <collision name='Wall_38_Collision_0'>
          <geometry>
            <box>
              <size>1.13532 0.15 2.5</size>
            </box>
          </geometry>
          <pose frame=''>-0.932339 0 1.25 0 -0 0</pose>
          <max_contacts>10</max_contacts>
          <surface>
            <contact>
              <ode/>
            </contact>
            <bounce/>
            <friction>
              <torsional>
                <ode/>
              </torsional>
              <ode/>
            </friction>
          </surface>
        </collision>
        <visual name='Wall_38_Visual_1'>
          <pose frame=''>0.567661 0 0.25 0 -0 0</pose>
          <geometry>
            <box>
              <size>1.86468 0.15 0.5</size>
            </box>
          </geometry>
          <material>
            <script>
              <uri>file://media/materials/scripts/gazebo.material</uri>
              <name>Gazebo/Bricks</name>
            </script>
            <ambient>0.921569 0.807843 0.615686 1</ambient>
          </material>
        </visual>
        <collision name='Wall_38_Collision_1'>
          <geometry>
            <box>
              <size>1.86468 0.15 0.5</size>
            </box>
          </geometry>
          <pose frame=''>0.567661 0 0.25 0 -0 0</pose>
          <max_contacts>10</max_contacts>
          <surface>
            <contact>
              <ode/>
            </contact>
            <bounce/>
            <friction>
              <torsional>
                <ode/>
              </torsional>
              <ode/>
            </friction>
          </surface>
        </collision>
        <visual name='Wall_38_Visual_2'>
          <pose frame=''>0.967661 0 1.5 0 -0 0</pose>
          <geometry>
            <box>
              <size>1.06468 0.15 2</size>
            </box>
          </geometry>
          <material>
            <script>
              <uri>file://media/materials/scripts/gazebo.material</uri>
              <name>Gazebo/Bricks</name>
            </script>
            <ambient>0.921569 0.807843 0.615686 1</ambient>
          </material>
        </visual>
        <collision name='Wall_38_Collision_2'>
          <geometry>
            <box>
              <size>1.06468 0.15 2</size>
            </box>
          </geometry>
          <pose frame=''>0.967661 0 1.5 0 -0 0</pose>
          <max_contacts>10</max_contacts>
          <surface>
            <contact>
              <ode/>
            </contact>
            <bounce/>
            <friction>
              <torsional>
                <ode/>
              </torsional>
              <ode/>
            </friction>
          </surface>
        </collision>
        <visual name='Wall_38_Visual_3'>
          <pose frame=''>0.035321 0 1.9 0 -0 0</pose>
          <geometry>
            <box>
              <size>0.8 0.15 1.2</size>
            </box>
          </geometry>
          <material>
            <script>
              <uri>file://media/materials/scripts/gazebo.material</uri>
              <name>Gazebo/Bricks</name>
            </script>
            <ambient>0.921569 0.807843 0.615686 1</ambient>
          </material>
        </visual>
        <collision name='Wall_38_Collision_3'>
          <geometry>
            <box>
              <size>0.8 0.15 1.2</size>
            </box>
          </geometry>
          <pose frame=''>0.035321 0 1.9 0 -0 0</pose>
          <max_contacts>10</max_contacts>
          <surface>
            <contact>
              <ode/>
            </contact>
            <bounce/>
            <friction>
              <torsional>
                <ode/>
              </torsional>
              <ode/>
            </friction>
          </surface>
        </collision>
        <self_collide>0</self_collide>
        <kinematic>0</kinematic>
        <gravity>1</gravity>
      </link>
      <link name='Wall_39'>
        <collision name='Wall_39_Collision'>
          <geometry>
            <box>
              <size>5 0.15 2.5</size>
            </box>
          </geometry>
          <pose frame=''>0 0 1.25 0 -0 0</pose>
          <max_contacts>10</max_contacts>
          <surface>
            <contact>
              <ode/>
            </contact>
            <bounce/>
            <friction>
              <torsional>
                <ode/>
              </torsional>
              <ode/>
            </friction>
          </surface>
        </collision>
        <visual name='Wall_39_Visual'>
          <pose frame=''>0 0 1.25 0 -0 0</pose>
          <geometry>
            <box>
              <size>5 0.15 2.5</size>
            </box>
          </geometry>
          <material>
            <script>
              <uri>file://media/materials/scripts/gazebo.material</uri>
              <name>Gazebo/Grey</name>
            </script>
            <ambient>0.921569 0.807843 0.615686 1</ambient>
          </material>
        </visual>
        <pose frame=''>2.075 1.5 0 0 0 -1.5708</pose>
        <self_collide>0</self_collide>
        <kinematic>0</kinematic>
        <gravity>1</gravity>
      </link>
      <link name='Wall_41'>
        <collision name='Wall_41_Collision'>
          <geometry>
            <box>
              <size>5 0.15 2.5</size>
            </box>
          </geometry>
          <pose frame=''>0 0 1.25 0 -0 0</pose>
          <max_contacts>10</max_contacts>
          <surface>
            <contact>
              <ode/>
            </contact>
            <bounce/>
            <friction>
              <torsional>
                <ode/>
              </torsional>
              <ode/>
            </friction>
          </surface>
        </collision>
        <visual name='Wall_41_Visual'>
          <pose frame=''>0 0 1.25 0 -0 0</pose>
          <geometry>
            <box>
              <size>5 0.15 2.5</size>
            </box>
          </geometry>
          <material>
            <script>
              <uri>file://media/materials/scripts/gazebo.material</uri>
              <name>Gazebo/Grey</name>
            </script>
            <ambient>0.921569 0.807843 0.615686 1</ambient>
          </material>
        </visual>
        <pose frame=''>-2.075 1.5 0 0 -0 1.5708</pose>
        <self_collide>0</self_collide>
        <kinematic>0</kinematic>
        <gravity>1</gravity>
      </link>
      <link name='Wall_42'>
        <pose frame=''>-3.5 3.925 0 0 -0 3.14159</pose>
        <visual name='Wall_42_Visual_0'>
          <pose frame=''>-0.947587 0 1.25 0 -0 0</pose>
          <geometry>
            <box>
              <size>1.10483 0.15 2.5</size>
            </box>
          </geometry>
          <material>
            <script>
              <uri>file://media/materials/scripts/gazebo.material</uri>
              <name>Gazebo/Bricks</name>
            </script>
            <ambient>0.921569 0.807843 0.615686 1</ambient>
          </material>
        </visual>
        <collision name='Wall_42_Collision_0'>
          <geometry>
            <box>
              <size>1.10483 0.15 2.5</size>
            </box>
          </geometry>
          <pose frame=''>-0.947587 0 1.25 0 -0 0</pose>
          <max_contacts>10</max_contacts>
          <surface>
            <contact>
              <ode/>
            </contact>
            <bounce/>
            <friction>
              <torsional>
                <ode/>
              </torsional>
              <ode/>
            </friction>
          </surface>
        </collision>
        <visual name='Wall_42_Visual_1'>
          <pose frame=''>1.00241 0 1.25 0 -0 0</pose>
          <geometry>
            <box>
              <size>0.995173 0.15 2.5</size>
            </box>
          </geometry>
          <material>
            <script>
              <uri>file://media/materials/scripts/gazebo.material</uri>
              <name>Gazebo/Bricks</name>
            </script>
            <ambient>0.921569 0.807843 0.615686 1</ambient>
          </material>
        </visual>
        <collision name='Wall_42_Collision_1'>
          <geometry>
            <box>
              <size>0.995173 0.15 2.5</size>
            </box>
          </geometry>
          <pose frame=''>1.00241 0 1.25 0 -0 0</pose>
          <max_contacts>10</max_contacts>
          <surface>
            <contact>
              <ode/>
            </contact>
            <bounce/>
            <friction>
              <torsional>
                <ode/>
              </torsional>
              <ode/>
            </friction>
          </surface>
        </collision>
        <visual name='Wall_42_Visual_2'>
          <pose frame=''>0.054827 0 2.25 0 -0 0</pose>
          <geometry>
            <box>
              <size>0.9 0.15 0.5</size>
            </box>
          </geometry>
          <material>
            <script>
              <uri>file://media/materials/scripts/gazebo.material</uri>
              <name>Gazebo/Bricks</name>
            </script>
            <ambient>0.921569 0.807843 0.615686 1</ambient>
          </material>
        </visual>
        <collision name='Wall_42_Collision_2'>
          <geometry>
            <box>
              <size>0.9 0.15 0.5</size>
            </box>
          </geometry>
          <pose frame=''>0.054827 0 2.25 0 -0 0</pose>
          <max_contacts>10</max_contacts>
          <surface>
            <contact>
              <ode/>
            </contact>
            <bounce/>
            <friction>
              <torsional>
                <ode/>
              </torsional>
              <ode/>
            </friction>
          </surface>
        </collision>
        <self_collide>0</self_collide>
        <kinematic>0</kinematic>
        <gravity>1</gravity>
      </link>
      <link name='Wall_44'>
        <pose frame=''>0 -0.925 0 0 -0 3.14159</pose>
        <visual name='Wall_44_Visual_0'>
          <pose frame=''>-1.7531 0 1.25 0 -0 0</pose>
          <geometry>
            <box>
              <size>0.793793 0.15 2.5</size>
            </box>
          </geometry>
          <material>
            <script>
              <uri>file://media/materials/scripts/gazebo.material</uri>
              <name>Gazebo/Grey</name>
            </script>
            <ambient>0.921569 0.807843 0.615686 1</ambient>
          </material>
        </visual>
        <collision name='Wall_44_Collision_0'>
          <geometry>
            <box>
              <size>0.793793 0.15 2.5</size>
            </box>
          </geometry>
          <pose frame=''>-1.7531 0 1.25 0 -0 0</pose>
          <max_contacts>10</max_contacts>
          <surface>
            <contact>
              <ode/>
            </contact>
            <bounce/>
            <friction>
              <torsional>
                <ode/>
              </torsional>
              <ode/>
            </friction>
          </surface>
        </collision>
        <visual name='Wall_44_Visual_1'>
          <pose frame=''>0.396896 0 0.25 0 -0 0</pose>
          <geometry>
            <box>
              <size>3.50621 0.15 0.5</size>
            </box>
          </geometry>
          <material>
            <script>
              <uri>file://media/materials/scripts/gazebo.material</uri>
              <name>Gazebo/Grey</name>
            </script>
            <ambient>0.921569 0.807843 0.615686 1</ambient>
          </material>
        </visual>
        <collision name='Wall_44_Collision_1'>
          <geometry>
            <box>
              <size>3.50621 0.15 0.5</size>
            </box>
          </geometry>
          <pose frame=''>0.396896 0 0.25 0 -0 0</pose>
          <max_contacts>10</max_contacts>
          <surface>
            <contact>
              <ode/>
            </contact>
            <bounce/>
            <friction>
              <torsional>
                <ode/>
              </torsional>
              <ode/>
            </friction>
          </surface>
        </collision>
        <visual name='Wall_44_Visual_2'>
          <pose frame=''>0.097773 0 1.5 0 -0 0</pose>
          <geometry>
            <box>
              <size>1.30796 0.15 2</size>
            </box>
          </geometry>
          <material>
            <script>
              <uri>file://media/materials/scripts/gazebo.material</uri>
              <name>Gazebo/Grey</name>
            </script>
            <ambient>0.921569 0.807843 0.615686 1</ambient>
          </material>
        </visual>
        <collision name='Wall_44_Collision_2'>
          <geometry>
            <box>
              <size>1.30796 0.15 2</size>
            </box>
          </geometry>
          <pose frame=''>0.097773 0 1.5 0 -0 0</pose>
          <max_contacts>10</max_contacts>
          <surface>
            <contact>
              <ode/>
            </contact>
            <bounce/>
            <friction>
              <torsional>
                <ode/>
              </torsional>
              <ode/>
            </friction>
          </surface>
        </collision>
        <visual name='Wall_44_Visual_3'>
          <pose frame=''>1.85088 0 1.5 0 -0 0</pose>
          <geometry>
            <box>
              <size>0.598248 0.15 2</size>
            </box>
          </geometry>
          <material>
            <script>
              <uri>file://media/materials/scripts/gazebo.material</uri>
              <name>Gazebo/Grey</name>
            </script>
            <ambient>0.921569 0.807843 0.615686 1</ambient>
          </material>
        </visual>
        <collision name='Wall_44_Collision_3'>
          <geometry>
            <box>
              <size>0.598248 0.15 2</size>
            </box>
          </geometry>
          <pose frame=''>1.85088 0 1.5 0 -0 0</pose>
          <max_contacts>10</max_contacts>
          <surface>
            <contact>
              <ode/>
            </contact>
            <bounce/>
            <friction>
              <torsional>
                <ode/>
              </torsional>
              <ode/>
            </friction>
          </surface>
        </collision>
        <visual name='Wall_44_Visual_4'>
          <pose frame=''>-0.956207 0 1.9 0 -0 0</pose>
          <geometry>
            <box>
              <size>0.8 0.15 1.2</size>
            </box>
          </geometry>
          <material>
            <script>
              <uri>file://media/materials/scripts/gazebo.material</uri>
              <name>Gazebo/Grey</name>
            </script>
            <ambient>0.921569 0.807843 0.615686 1</ambient>
          </material>
        </visual>
        <collision name='Wall_44_Collision_4'>
          <geometry>
            <box>
              <size>0.8 0.15 1.2</size>
            </box>
          </geometry>
          <pose frame=''>-0.956207 0 1.9 0 -0 0</pose>
          <max_contacts>10</max_contacts>
          <surface>
            <contact>
              <ode/>
            </contact>
            <bounce/>
            <friction>
              <torsional>
                <ode/>
              </torsional>
              <ode/>
            </friction>
          </surface>
        </collision>
        <visual name='Wall_44_Visual_5'>
          <pose frame=''>1.15175 0 1.9 0 -0 0</pose>
          <geometry>
            <box>
              <size>0.8 0.15 1.2</size>
            </box>
          </geometry>
          <material>
            <script>
              <uri>file://media/materials/scripts/gazebo.material</uri>
              <name>Gazebo/Grey</name>
            </script>
            <ambient>0.921569 0.807843 0.615686 1</ambient>
          </material>
        </visual>
        <collision name='Wall_44_Collision_5'>
          <geometry>
            <box>
              <size>0.8 0.15 1.2</size>
            </box>
          </geometry>
          <pose frame=''>1.15175 0 1.9 0 -0 0</pose>
          <max_contacts>10</max_contacts>
          <surface>
            <contact>
              <ode/>
            </contact>
            <bounce/>
            <friction>
              <torsional>
                <ode/>
              </torsional>
              <ode/>
            </friction>
          </surface>
        </collision>
        <self_collide>0</self_collide>
        <kinematic>0</kinematic>
        <gravity>1</gravity>
      </link>
      <link name='Wall_46'>
        <collision name='Wall_46_Collision'>
          <geometry>
            <box>
              <size>8 0.15 2.5</size>
            </box>
          </geometry>
          <pose frame=''>0 0 1.25 0 -0 0</pose>
          <max_contacts>10</max_contacts>
          <surface>
            <contact>
              <ode/>
            </contact>
            <bounce/>
            <friction>
              <torsional>
                <ode/>
              </torsional>
              <ode/>
            </friction>
          </surface>
        </collision>
        <visual name='Wall_46_Visual'>
          <pose frame=''>0 0 1.25 0 -0 0</pose>
          <geometry>
            <box>
              <size>8 0.15 2.5</size>
            </box>
          </geometry>
          <material>
            <script>
              <uri>file://media/materials/scripts/gazebo.material</uri>
              <name>Gazebo/Grey</name>
            </script>
            <ambient>0.760784 0.662745 0.627451 1</ambient>
          </material>
        </visual>
        <pose frame=''>-4.925 0 0 0 0 -1.5708</pose>
        <self_collide>0</self_collide>
        <kinematic>0</kinematic>
        <gravity>1</gravity>
      </link>
      <link name='Wall_48'>
        <collision name='Wall_48_Collision'>
          <geometry>
            <box>
              <size>8 0.15 2.5</size>
            </box>
          </geometry>
          <pose frame=''>0 0 1.25 0 -0 0</pose>
          <max_contacts>10</max_contacts>
          <surface>
            <contact>
              <ode/>
            </contact>
            <bounce/>
            <friction>
              <torsional>
                <ode/>
              </torsional>
              <ode/>
            </friction>
          </surface>
        </collision>
        <visual name='Wall_48_Visual'>
          <pose frame=''>0 0 1.25 0 -0 0</pose>
          <geometry>
            <box>
              <size>8 0.15 2.5</size>
            </box>
          </geometry>
          <material>
            <script>
              <uri>file://media/materials/scripts/gazebo.material</uri>
              <name>Gazebo/Grey</name>
            </script>
            <ambient>0.760784 0.662745 0.627451 1</ambient>
          </material>
        </visual>
        <pose frame=''>4.925 0 0 0 0 -1.5708</pose>
        <self_collide>0</self_collide>
        <kinematic>0</kinematic>
        <gravity>1</gravity>
      </link>
      <static>1</static>
    </model>
    <gui fullscreen='0'>
      <camera name='user_camera'>
        <pose frame=''>2.92732 -9.10626 28.3424 0 1.29164 1.5482</pose>
        <view_controller>orbit</view_controller>
        <projection_type>perspective</projection_type>
      </camera>
    </gui>
    <plugin name='collision_map_creator' filename='libcollision_map_creator.so'/>
    <model name='cabinet'>
      <static>1</static>
      <link name='cabinet_bottom_plate'>
        <inertial>
          <pose frame=''>0 0 -1 0 -0 0</pose>
          <inertia>
            <ixx>2.05</ixx>
            <ixy>0</ixy>
            <ixz>0</ixz>
            <iyy>2.05</iyy>
            <iyz>0</iyz>
            <izz>2.05</izz>
          </inertia>
          <mass>25</mass>
        </inertial>
        <collision name='cabinet_bottom_plate_geom'>
          <pose frame=''>0 0 0.01 0 -0 0</pose>
          <geometry>
            <box>
              <size>0.45 0.45 0.02</size>
            </box>
          </geometry>
          <max_contacts>10</max_contacts>
          <surface>
            <contact>
              <ode/>
            </contact>
            <bounce/>
            <friction>
              <torsional>
                <ode/>
              </torsional>
              <ode/>
            </friction>
          </surface>
        </collision>
        <visual name='cabinet_bottom_plate_geom_visual'>
          <pose frame=''>0 0 0.01 0 -0 0</pose>
          <geometry>
            <box>
              <size>0.45 0.45 0.02</size>
            </box>
          </geometry>
          <material>
            <script>
              <uri>file://media/materials/scripts/gazebo.material</uri>
              <name>Gazebo/Wood</name>
            </script>
          </material>
        </visual>
        <collision name='cabinet_bottom_plate_geom_cabinet_back_plate'>
          <pose frame=''>0.235 0 0.51 0 -0 0</pose>
          <geometry>
            <box>
              <size>0.02 0.45 1.02</size>
            </box>
          </geometry>
          <max_contacts>10</max_contacts>
          <surface>
            <contact>
              <ode/>
            </contact>
            <bounce/>
            <friction>
              <torsional>
                <ode/>
              </torsional>
              <ode/>
            </friction>
          </surface>
        </collision>
        <visual name='cabinet_bottom_plate_geom_cabinet_back_plate_visual'>
          <pose frame=''>0.235 0 0.51 0 -0 0</pose>
          <geometry>
            <box>
              <size>0.02 0.45 1.02</size>
            </box>
          </geometry>
          <material>
            <script>
              <uri>file://media/materials/scripts/gazebo.material</uri>
              <name>Gazebo/Wood</name>
            </script>
          </material>
        </visual>
        <collision name='cabinet_bottom_plate_geom_cabinet_left_plate'>
          <pose frame=''>0 0.235 0.51 0 -0 0</pose>
          <geometry>
            <box>
              <size>0.45 0.02 1.02</size>
            </box>
          </geometry>
          <max_contacts>10</max_contacts>
          <surface>
            <contact>
              <ode/>
            </contact>
            <bounce/>
            <friction>
              <torsional>
                <ode/>
              </torsional>
              <ode/>
            </friction>
          </surface>
        </collision>
        <visual name='cabinet_bottom_plate_geom_cabinet_left_plate_visual'>
          <pose frame=''>0 0.235 0.51 0 -0 0</pose>
          <geometry>
            <box>
              <size>0.45 0.02 1.02</size>
            </box>
          </geometry>
          <material>
            <script>
              <uri>file://media/materials/scripts/gazebo.material</uri>
              <name>Gazebo/Wood</name>
            </script>
          </material>
        </visual>
        <collision name='cabinet_bottom_plate_geom_cabinet_middle_plate'>
          <pose frame=''>0 0 0.51 0 -0 0</pose>
          <geometry>
            <box>
              <size>0.45 0.45 0.02</size>
            </box>
          </geometry>
          <max_contacts>10</max_contacts>
          <surface>
            <contact>
              <ode/>
            </contact>
            <bounce/>
            <friction>
              <torsional>
                <ode/>
              </torsional>
              <ode/>
            </friction>
          </surface>
        </collision>
        <visual name='cabinet_bottom_plate_geom_cabinet_middle_plate_visual'>
          <pose frame=''>0 0 0.51 0 -0 0</pose>
          <geometry>
            <box>
              <size>0.45 0.45 0.02</size>
            </box>
          </geometry>
          <material>
            <script>
              <uri>file://media/materials/scripts/gazebo.material</uri>
              <name>Gazebo/Wood</name>
            </script>
          </material>
        </visual>
        <collision name='cabinet_bottom_plate_geom_cabinet_right_plate'>
          <pose frame=''>0 -0.235 0.51 0 -0 0</pose>
          <geometry>
            <box>
              <size>0.45 0.02 1.02</size>
            </box>
          </geometry>
          <max_contacts>10</max_contacts>
          <surface>
            <contact>
              <ode/>
            </contact>
            <bounce/>
            <friction>
              <torsional>
                <ode/>
              </torsional>
              <ode/>
            </friction>
          </surface>
        </collision>
        <visual name='cabinet_bottom_plate_geom_cabinet_right_plate_visual'>
          <pose frame=''>0 -0.235 0.51 0 -0 0</pose>
          <geometry>
            <box>
              <size>0.45 0.02 1.02</size>
            </box>
          </geometry>
          <material>
            <script>
              <uri>file://media/materials/scripts/gazebo.material</uri>
              <name>Gazebo/Wood</name>
            </script>
          </material>
        </visual>
        <collision name='cabinet_bottom_plate_geom_cabinet_top_plate'>
          <pose frame=''>0 0 1.01 0 -0 0</pose>
          <geometry>
            <box>
              <size>0.45 0.45 0.02</size>
            </box>
          </geometry>
          <max_contacts>10</max_contacts>
          <surface>
            <contact>
              <ode/>
            </contact>
            <bounce/>
            <friction>
              <torsional>
                <ode/>
              </torsional>
              <ode/>
            </friction>
          </surface>
        </collision>
        <visual name='cabinet_bottom_plate_geom_cabinet_top_plate_visual'>
          <pose frame=''>0 0 1.01 0 -0 0</pose>
          <geometry>
            <box>
              <size>0.45 0.45 0.02</size>
            </box>
          </geometry>
          <material>
            <script>
              <uri>file://media/materials/scripts/gazebo.material</uri>
              <name>Gazebo/Wood</name>
            </script>
          </material>
        </visual>
        <self_collide>0</self_collide>
        <kinematic>0</kinematic>
        <gravity>1</gravity>
      </link>
      <pose frame=''>0.941746 0.365453 0 0 -0 0</pose>
    </model>
    <model name='bookshelf'>
      <static>1</static>
      <link name='link'>
        <inertial>
          <mass>1</mass>
        </inertial>
        <collision name='back'>
          <pose frame=''>0 0.005 0.6 0 -0 0</pose>
          <geometry>
            <box>
              <size>0.9 0.01 1.2</size>
            </box>
          </geometry>
          <max_contacts>10</max_contacts>
          <surface>
            <contact>
              <ode/>
            </contact>
            <bounce/>
            <friction>
              <torsional>
                <ode/>
              </torsional>
              <ode/>
            </friction>
          </surface>
        </collision>
        <visual name='visual1'>
          <pose frame=''>0 0.005 0.6 0 -0 0</pose>
          <geometry>
            <box>
              <size>0.9 0.01 1.2</size>
            </box>
          </geometry>
          <material>
            <script>
              <uri>file://media/materials/scripts/gazebo.material</uri>
              <name>Gazebo/Wood</name>
            </script>
          </material>
        </visual>
        <collision name='left_side'>
          <pose frame=''>0.45 -0.195 0.6 0 -0 0</pose>
          <geometry>
            <box>
              <size>0.02 0.4 1.2</size>
            </box>
          </geometry>
          <max_contacts>10</max_contacts>
          <surface>
            <contact>
              <ode/>
            </contact>
            <bounce/>
            <friction>
              <torsional>
                <ode/>
              </torsional>
              <ode/>
            </friction>
          </surface>
        </collision>
        <visual name='visual2'>
          <pose frame=''>0.45 -0.195 0.6 0 -0 0</pose>
          <geometry>
            <box>
              <size>0.02 0.4 1.2</size>
            </box>
          </geometry>
          <material>
            <script>
              <uri>file://media/materials/scripts/gazebo.material</uri>
              <name>Gazebo/Wood</name>
            </script>
          </material>
        </visual>
        <collision name='right_side'>
          <pose frame=''>-0.45 -0.195 0.6 0 -0 0</pose>
          <geometry>
            <box>
              <size>0.02 0.4 1.2</size>
            </box>
          </geometry>
          <max_contacts>10</max_contacts>
          <surface>
            <contact>
              <ode/>
            </contact>
            <bounce/>
            <friction>
              <torsional>
                <ode/>
              </torsional>
              <ode/>
            </friction>
          </surface>
        </collision>
        <visual name='visual3'>
          <pose frame=''>-0.45 -0.195 0.6 0 -0 0</pose>
          <geometry>
            <box>
              <size>0.02 0.4 1.2</size>
            </box>
          </geometry>
          <material>
            <script>
              <uri>file://media/materials/scripts/gazebo.material</uri>
              <name>Gazebo/Wood</name>
            </script>
          </material>
        </visual>
        <collision name='bottom'>
          <pose frame=''>0 -0.195 0.03 0 -0 0</pose>
          <geometry>
            <box>
              <size>0.88 0.4 0.06</size>
            </box>
          </geometry>
          <max_contacts>10</max_contacts>
          <surface>
            <contact>
              <ode/>
            </contact>
            <bounce/>
            <friction>
              <torsional>
                <ode/>
              </torsional>
              <ode/>
            </friction>
          </surface>
        </collision>
        <visual name='visual4'>
          <pose frame=''>0 -0.195 0.03 0 -0 0</pose>
          <geometry>
            <box>
              <size>0.88 0.4 0.06</size>
            </box>
          </geometry>
          <material>
            <script>
              <uri>file://media/materials/scripts/gazebo.material</uri>
              <name>Gazebo/Wood</name>
            </script>
          </material>
        </visual>
        <collision name='top'>
          <pose frame=''>0 -0.195 1.19 0 -0 0</pose>
          <geometry>
            <box>
              <size>0.88 0.4 0.02</size>
            </box>
          </geometry>
          <max_contacts>10</max_contacts>
          <surface>
            <contact>
              <ode/>
            </contact>
            <bounce/>
            <friction>
              <torsional>
                <ode/>
              </torsional>
              <ode/>
            </friction>
          </surface>
        </collision>
        <visual name='visual5'>
          <pose frame=''>0 -0.195 1.19 0 -0 0</pose>
          <geometry>
            <box>
              <size>0.88 0.4 0.02</size>
            </box>
          </geometry>
          <material>
            <script>
              <uri>file://media/materials/scripts/gazebo.material</uri>
              <name>Gazebo/Wood</name>
            </script>
          </material>
        </visual>
        <collision name='low_shelf'>
          <pose frame=''>0 -0.195 0.43 0 -0 0</pose>
          <geometry>
            <box>
              <size>0.88 0.4 0.02</size>
            </box>
          </geometry>
          <max_contacts>10</max_contacts>
          <surface>
            <contact>
              <ode/>
            </contact>
            <bounce/>
            <friction>
              <torsional>
                <ode/>
              </torsional>
              <ode/>
            </friction>
          </surface>
        </collision>
        <visual name='visual6'>
          <pose frame=''>0 -0.195 0.43 0 -0 0</pose>
          <geometry>
            <box>
              <size>0.88 0.4 0.02</size>
            </box>
          </geometry>
          <material>
            <script>
              <uri>file://media/materials/scripts/gazebo.material</uri>
              <name>Gazebo/Wood</name>
            </script>
          </material>
        </visual>
        <collision name='high_shelf'>
          <pose frame=''>0 -0.195 0.8 0 -0 0</pose>
          <geometry>
            <box>
              <size>0.88 0.4 0.02</size>
            </box>
          </geometry>
          <max_contacts>10</max_contacts>
          <surface>
            <contact>
              <ode/>
            </contact>
            <bounce/>
            <friction>
              <torsional>
                <ode/>
              </torsional>
              <ode/>
            </friction>
          </surface>
        </collision>
        <visual name='visual7'>
          <pose frame=''>0 -0.195 0.8 0 -0 0</pose>
          <geometry>
            <box>
              <size>0.88 0.4 0.02</size>
            </box>
          </geometry>
          <material>
            <script>
              <uri>file://media/materials/scripts/gazebo.material</uri>
              <name>Gazebo/Wood</name>
            </script>
          </material>
        </visual>
        <self_collide>0</self_collide>
        <kinematic>0</kinematic>
        <gravity>1</gravity>
      </link>
      <pose frame=''>3.32468 -4.28542 0 0 -0 0</pose>
    </model>
    <model name='mars_rover'>
      <static>1</static>
      <link name='link'>
        <collision name='solar_panel_collision'>
          <pose frame=''>0 -0.06945 0.47293 0 -0 0</pose>
          <geometry>
            <box>
              <size>0.87974 0.8821 0.02602</size>
            </box>
          </geometry>
          <max_contacts>10</max_contacts>
          <surface>
            <contact>
              <ode/>
            </contact>
            <bounce/>
            <friction>
              <torsional>
                <ode/>
              </torsional>
              <ode/>
            </friction>
          </surface>
        </collision>
        <collision name='chassis_collision'>
          <pose frame=''>0 -0.05 0.31475 0 -0 0</pose>
          <geometry>
            <box>
              <size>0.49522 0.67401 0.28915</size>
            </box>
          </geometry>
          <max_contacts>10</max_contacts>
          <surface>
            <contact>
              <ode/>
            </contact>
            <bounce/>
            <friction>
              <torsional>
                <ode/>
              </torsional>
              <ode/>
            </friction>
          </surface>
        </collision>
        <collision name='rear_left_bumper_collision'>
          <pose frame=''>0.30107 0.3835 0.38976 0 -0 0</pose>
          <geometry>
            <box>
              <size>0.04442 0.38897 0.07918</size>
            </box>
          </geometry>
          <max_contacts>10</max_contacts>
          <surface>
            <contact>
              <ode/>
            </contact>
            <bounce/>
            <friction>
              <torsional>
                <ode/>
              </torsional>
              <ode/>
            </friction>
          </surface>
        </collision>
        <collision name='rear_right_bumper_collision'>
          <pose frame=''>-0.30107 0.3835 0.38976 0 -0 0</pose>
          <geometry>
            <box>
              <size>0.04442 0.38897 0.07918</size>
            </box>
          </geometry>
          <max_contacts>10</max_contacts>
          <surface>
            <contact>
              <ode/>
            </contact>
            <bounce/>
            <friction>
              <torsional>
                <ode/>
              </torsional>
              <ode/>
            </friction>
          </surface>
        </collision>
        <collision name='rear_bumper_collision'>
          <pose frame=''>0 0.59414 0.38976 0 -0 0</pose>
          <geometry>
            <box>
              <size>0.56656 0.04442 0.07918</size>
            </box>
          </geometry>
          <max_contacts>10</max_contacts>
          <surface>
            <contact>
              <ode/>
            </contact>
            <bounce/>
            <friction>
              <torsional>
                <ode/>
              </torsional>
              <ode/>
            </friction>
          </surface>
        </collision>
        <collision name='bin_back_panel_collision'>
          <pose frame=''>0 0.47 0.32114 0.69137 -0 0</pose>
          <geometry>
            <box>
              <size>0.43774 0.212366 0.05173</size>
            </box>
          </geometry>
          <max_contacts>10</max_contacts>
          <surface>
            <contact>
              <ode/>
            </contact>
            <bounce/>
            <friction>
              <torsional>
                <ode/>
              </torsional>
              <ode/>
            </friction>
          </surface>
        </collision>
        <collision name='bin_left_panel_collision1'>
          <pose frame=''>0.22615 0.32897 0.33193 0 -0 0</pose>
          <geometry>
            <box>
              <size>0.01116 0.19338 0.16304</size>
            </box>
          </geometry>
          <max_contacts>10</max_contacts>
          <surface>
            <contact>
              <ode/>
            </contact>
            <bounce/>
            <friction>
              <torsional>
                <ode/>
              </torsional>
              <ode/>
            </friction>
          </surface>
        </collision>
        <collision name='bin_left_panel_collision2'>
          <pose frame=''>0.22615 0.471 0.39308 0 -0 0</pose>
          <geometry>
            <box>
              <size>0.01116 0.15 0.04</size>
            </box>
          </geometry>
          <max_contacts>10</max_contacts>
          <surface>
            <contact>
              <ode/>
            </contact>
            <bounce/>
            <friction>
              <torsional>
                <ode/>
              </torsional>
              <ode/>
            </friction>
          </surface>
        </collision>
        <collision name='bin_left_panel_collision3'>
          <pose frame=''>0.22615 0.45 0.35308 0 -0 0</pose>
          <geometry>
            <box>
              <size>0.01116 0.15 0.04</size>
            </box>
          </geometry>
          <max_contacts>10</max_contacts>
          <surface>
            <contact>
              <ode/>
            </contact>
            <bounce/>
            <friction>
              <torsional>
                <ode/>
              </torsional>
              <ode/>
            </friction>
          </surface>
        </collision>
        <collision name='bin_left_panel_collision4'>
          <pose frame=''>0.22615 0.39308 0.31308 0 -0 0</pose>
          <geometry>
            <box>
              <size>0.01116 0.15 0.04</size>
            </box>
          </geometry>
          <max_contacts>10</max_contacts>
          <surface>
            <contact>
              <ode/>
            </contact>
            <bounce/>
            <friction>
              <torsional>
                <ode/>
              </torsional>
              <ode/>
            </friction>
          </surface>
        </collision>
        <collision name='bin_right_panel_collision1'>
          <pose frame=''>-0.22615 0.32897 0.33193 0 -0 0</pose>
          <geometry>
            <box>
              <size>0.01116 0.19338 0.16304</size>
            </box>
          </geometry>
          <max_contacts>10</max_contacts>
          <surface>
            <contact>
              <ode/>
            </contact>
            <bounce/>
            <friction>
              <torsional>
                <ode/>
              </torsional>
              <ode/>
            </friction>
          </surface>
        </collision>
        <collision name='bin_right_panel_collision2'>
          <pose frame=''>-0.22615 0.471 0.39308 0 -0 0</pose>
          <geometry>
            <box>
              <size>0.01116 0.15 0.04</size>
            </box>
          </geometry>
          <max_contacts>10</max_contacts>
          <surface>
            <contact>
              <ode/>
            </contact>
            <bounce/>
            <friction>
              <torsional>
                <ode/>
              </torsional>
              <ode/>
            </friction>
          </surface>
        </collision>
        <collision name='bin_right_panel_collision3'>
          <pose frame=''>-0.22615 0.45 0.35308 0 -0 0</pose>
          <geometry>
            <box>
              <size>0.01116 0.15 0.04</size>
            </box>
          </geometry>
          <max_contacts>10</max_contacts>
          <surface>
            <contact>
              <ode/>
            </contact>
            <bounce/>
            <friction>
              <torsional>
                <ode/>
              </torsional>
              <ode/>
            </friction>
          </surface>
        </collision>
        <collision name='bin_right_panel_collision4'>
          <pose frame=''>-0.22615 0.39308 0.31308 0 -0 0</pose>
          <geometry>
            <box>
              <size>0.01116 0.15 0.04</size>
            </box>
          </geometry>
          <max_contacts>10</max_contacts>
          <surface>
            <contact>
              <ode/>
            </contact>
            <bounce/>
            <friction>
              <torsional>
                <ode/>
              </torsional>
              <ode/>
            </friction>
          </surface>
        </collision>
        <collision name='bin_front_panel_collision'>
          <pose frame=''>0 0.30047 0.32114 2.26207 -0 0</pose>
          <geometry>
            <box>
              <size>0.43774 0.212366 0.05173</size>
            </box>
          </geometry>
          <max_contacts>10</max_contacts>
          <surface>
            <contact>
              <ode/>
            </contact>
            <bounce/>
            <friction>
              <torsional>
                <ode/>
              </torsional>
              <ode/>
            </friction>
          </surface>
        </collision>
        <collision name='front_left_wheel_collision'>
          <pose frame=''>0.31103 -0.32115 0.1358 1.5707 0 1.5707</pose>
          <geometry>
            <cylinder>
              <radius>0.1358</radius>
              <length>0.1641</length>
            </cylinder>
          </geometry>
          <max_contacts>10</max_contacts>
          <surface>
            <contact>
              <ode/>
            </contact>
            <bounce/>
            <friction>
              <torsional>
                <ode/>
              </torsional>
              <ode/>
            </friction>
          </surface>
        </collision>
        <collision name='front_right_wheel_collision'>
          <pose frame=''>-0.31103 -0.32115 0.1358 1.5707 0 1.5707</pose>
          <geometry>
            <cylinder>
              <radius>0.1358</radius>
              <length>0.1641</length>
            </cylinder>
          </geometry>
          <max_contacts>10</max_contacts>
          <surface>
            <contact>
              <ode/>
            </contact>
            <bounce/>
            <friction>
              <torsional>
                <ode/>
              </torsional>
              <ode/>
            </friction>
          </surface>
        </collision>
        <collision name='rear_left_wheel_collision'>
          <pose frame=''>0.31103 0.28049 0.1358 1.5707 0 1.5707</pose>
          <geometry>
            <cylinder>
              <radius>0.1358</radius>
              <length>0.1641</length>
            </cylinder>
          </geometry>
          <max_contacts>10</max_contacts>
          <surface>
            <contact>
              <ode/>
            </contact>
            <bounce/>
            <friction>
              <torsional>
                <ode/>
              </torsional>
              <ode/>
            </friction>
          </surface>
        </collision>
        <collision name='rear_right_wheel_collision'>
          <pose frame=''>-0.31103 0.28049 0.1358 1.5707 0 1.5707</pose>
          <geometry>
            <cylinder>
              <radius>0.1358</radius>
              <length>0.1641</length>
            </cylinder>
          </geometry>
          <max_contacts>10</max_contacts>
          <surface>
            <contact>
              <ode/>
            </contact>
            <bounce/>
            <friction>
              <torsional>
                <ode/>
              </torsional>
              <ode/>
            </friction>
          </surface>
        </collision>
        <visual name='visual'>
          <geometry>
            <mesh>
              <uri>model://mars_rover/meshes/rover.dae</uri>
              <scale>1 1 1</scale>
            </mesh>
          </geometry>
        </visual>
        <self_collide>0</self_collide>
        <kinematic>0</kinematic>
        <gravity>1</gravity>
      </link>
      <pose frame=''>7.24994 -6.23589 0 0 -0 0</pose>
    </model>
    <model name='youbot'>
      <pose frame=''>6.08201 0.24911 0.09 0 -0 0</pose>
      <link name='base_footprint'>
        <pose frame=''>0 0 0 0 -0 0</pose>
        <inertial>
          <pose frame=''>0 0 -0.05 0 -0 0</pose>
          <inertia>
            <ixx>1</ixx>
            <ixy>0</ixy>
            <ixz>0</ixz>
            <iyy>1</iyy>
            <iyz>0</iyz>
            <izz>1</izz>
          </inertia>
          <mass>0.1</mass>
        </inertial>
        <collision name='base_footprint_geom'>
          <pose frame=''>0 0 -0.05 0 -0 0</pose>
          <geometry>
            <box>
              <size>0.001 0.001 0.001</size>
            </box>
          </geometry>
          <surface>
            <friction>
              <ode>
                <mu>0</mu>
                <mu2>0</mu2>
                <fdir1>0 0 0</fdir1>
                <slip1>0</slip1>
                <slip2>0</slip2>
              </ode>
              <torsional>
                <ode/>
              </torsional>
            </friction>
            <bounce>
              <restitution_coefficient>0</restitution_coefficient>
              <threshold>0</threshold>
            </bounce>
            <contact>
              <ode>
                <soft_cfm>0</soft_cfm>
                <soft_erp>0.2</soft_erp>
                <kp>1e+13</kp>
                <kd>1e+11</kd>
                <max_vel>-1</max_vel>
                <min_depth>0</min_depth>
              </ode>
            </contact>
          </surface>
          <laser_retro>0</laser_retro>
          <max_contacts>10</max_contacts>
        </collision>
        <visual name='base_footprint_geom_visual'>
          <pose frame=''>0 0 0 0 -0 0</pose>
          <geometry>
            <box>
              <size>0.001 0.001 0.001</size>
            </box>
          </geometry>
        </visual>
        <gravity>1</gravity>
        <self_collide>0</self_collide>
        <kinematic>0</kinematic>
      </link>
      <link name='base_link'>
        <pose frame=''>0 0 0 0 -0 0</pose>
        <inertial>
          <pose frame=''>0 0 0 0 -0 0</pose>
          <inertia>
            <ixx>5.65223</ixx>
            <ixy>-0.00972</ixy>
            <ixz>1.29399</ixz>
            <iyy>5.66947</iyy>
            <iyz>-0.00738</iyz>
            <izz>3.6832</izz>
          </inertia>
          <mass>22</mass>
        </inertial>
        <collision name='base_link_geom'>
          <pose frame=''>0 0 0 0 -0 0</pose>
          <geometry>
            <mesh>
              <uri>model://youbot/meshes/base/base_convex.stl</uri>
              <scale>1 1 1</scale>
            </mesh>
          </geometry>
          <surface>
            <friction>
              <ode>
                <mu>0</mu>
                <mu2>0</mu2>
                <fdir1>0 0 0</fdir1>
                <slip1>0</slip1>
                <slip2>0</slip2>
              </ode>
              <torsional>
                <ode/>
              </torsional>
            </friction>
            <bounce>
              <restitution_coefficient>0</restitution_coefficient>
              <threshold>0</threshold>
            </bounce>
            <contact>
              <ode>
                <soft_cfm>0</soft_cfm>
                <soft_erp>0.2</soft_erp>
                <kp>1e+13</kp>
                <kd>1e+11</kd>
                <max_vel>-1</max_vel>
                <min_depth>0</min_depth>
              </ode>
            </contact>
          </surface>
          <laser_retro>0</laser_retro>
          <max_contacts>10</max_contacts>
        </collision>
        <visual name='base_link_geom_visual'>
          <pose frame=''>0 0 0 0 -0 0</pose>
          <geometry>
            <mesh>
              <uri>model://youbot/meshes/base/base.dae</uri>
              <scale>1 1 1</scale>
            </mesh>
          </geometry>
        </visual>
        <gravity>1</gravity>
        <self_collide>0</self_collide>
        <kinematic>0</kinematic>
      </link>
      <link name='arm_link_0'>
        <pose frame=''>0.143 0 0.046 0 -0 0</pose>
        <inertial>
          <pose frame=''>0 0 0 0 -0 0</pose>
          <inertia>
            <ixx>0.01</ixx>
            <ixy>0</ixy>
            <ixz>0</ixz>
            <iyy>0.01</iyy>
            <iyz>0</iyz>
            <izz>0.01</izz>
          </inertia>
          <mass>0.845</mass>
        </inertial>
        <collision name='arm_link_0_geom'>
          <pose frame=''>0 0 0 0 -0 0</pose>
          <geometry>
            <mesh>
              <uri>model://youbot/meshes/arm/arm0_convex.stl</uri>
              <scale>1 1 1</scale>
            </mesh>
          </geometry>
          <surface>
            <friction>
              <ode>
                <mu>0</mu>
                <mu2>0</mu2>
                <fdir1>0 0 0</fdir1>
                <slip1>0</slip1>
                <slip2>0</slip2>
              </ode>
              <torsional>
                <ode/>
              </torsional>
            </friction>
            <bounce>
              <restitution_coefficient>0</restitution_coefficient>
              <threshold>0</threshold>
            </bounce>
            <contact>
              <ode>
                <soft_cfm>0</soft_cfm>
                <soft_erp>0.2</soft_erp>
                <kp>1e+13</kp>
                <kd>1e+11</kd>
                <max_vel>-1</max_vel>
                <min_depth>0</min_depth>
              </ode>
            </contact>
          </surface>
          <laser_retro>0</laser_retro>
          <max_contacts>10</max_contacts>
        </collision>
        <visual name='arm_link_0_geom_visual'>
          <pose frame=''>0 0 0 0 -0 0</pose>
          <geometry>
            <mesh>
              <uri>model://youbot/meshes/arm/arm0.dae</uri>
              <scale>1 1 1</scale>
            </mesh>
          </geometry>
          <material>
            <script>
              <uri>model://youbot/materials/scripts/youbot.material</uri>
              <name>youbot/DarkGrey</name>
            </script>
          </material>
        </visual>
        <gravity>1</gravity>
        <self_collide>0</self_collide>
        <kinematic>0</kinematic>
      </link>
      <link name='arm_link_1'>
        <pose frame=''>0.167 0 0.142 0 -0 2.96706</pose>
        <inertial>
          <pose frame=''>0.01489 0.00213 0.00213 0 -0 0</pose>
          <inertia>
            <ixx>0.003863</ixx>
            <ixy>-0.000979</ixy>
            <ixz>0</ixz>
            <iyy>0.006196</iyy>
            <iyz>0</iyz>
            <izz>0.006369</izz>
          </inertia>
          <mass>2.412</mass>
        </inertial>
        <collision name='arm_link_1_geom'>
          <pose frame=''>0 0 0 0 -0 0</pose>
          <geometry>
            <mesh>
              <uri>model://youbot/meshes/arm/arm1_convex.stl</uri>
              <scale>1 1 1</scale>
            </mesh>
          </geometry>
          <surface>
            <friction>
              <ode>
                <mu>0</mu>
                <mu2>0</mu2>
                <fdir1>0 0 0</fdir1>
                <slip1>0</slip1>
                <slip2>0</slip2>
              </ode>
              <torsional>
                <ode/>
              </torsional>
            </friction>
            <bounce>
              <restitution_coefficient>0</restitution_coefficient>
              <threshold>0</threshold>
            </bounce>
            <contact>
              <ode>
                <soft_cfm>0</soft_cfm>
                <soft_erp>0.2</soft_erp>
                <kp>1e+13</kp>
                <kd>1e+11</kd>
                <max_vel>-1</max_vel>
                <min_depth>0</min_depth>
              </ode>
            </contact>
          </surface>
          <laser_retro>0</laser_retro>
          <max_contacts>10</max_contacts>
        </collision>
        <visual name='arm_link_1_geom_visual'>
          <pose frame=''>0 0 0 0 -0 0</pose>
          <geometry>
            <mesh>
              <uri>model://youbot/meshes/arm/arm1.dae</uri>
              <scale>1 1 1</scale>
            </mesh>
          </geometry>
        </visual>
        <gravity>1</gravity>
        <self_collide>0</self_collide>
        <kinematic>0</kinematic>
      </link>
      <link name='arm_link_2'>
        <pose frame=''>0.134501 0.00573 0.161 0 -1.13446 2.96706</pose>
        <inertial>
          <pose frame=''>0.10453 0.0017 -0.00297 0 -0 0</pose>
          <inertia>
            <ixx>0.000823</ixx>
            <ixy>0</ixy>
            <ixz>-0</ixz>
            <iyy>0.004447</iyy>
            <iyz>0</iyz>
            <izz>0.004439</izz>
          </inertia>
          <mass>1.155</mass>
        </inertial>
        <collision name='arm_link_2_geom'>
          <pose frame=''>0 -0.032 0.078 0 -0 0</pose>
          <geometry>
            <mesh>
              <uri>model://youbot/meshes/arm/arm2_convex.stl</uri>
              <scale>1 1 1</scale>
            </mesh>
          </geometry>
          <surface>
            <friction>
              <ode>
                <mu>0</mu>
                <mu2>0</mu2>
                <fdir1>0 0 0</fdir1>
                <slip1>0</slip1>
                <slip2>0</slip2>
              </ode>
              <torsional>
                <ode/>
              </torsional>
            </friction>
            <bounce>
              <restitution_coefficient>0</restitution_coefficient>
              <threshold>0</threshold>
            </bounce>
            <contact>
              <ode>
                <soft_cfm>0</soft_cfm>
                <soft_erp>0.2</soft_erp>
                <kp>1e+13</kp>
                <kd>1e+11</kd>
                <max_vel>-1</max_vel>
                <min_depth>0</min_depth>
              </ode>
            </contact>
          </surface>
          <laser_retro>0</laser_retro>
          <max_contacts>10</max_contacts>
        </collision>
        <visual name='arm_link_2_geom_visual'>
          <pose frame=''>0 -0.032 0.078 0 -0 0</pose>
          <geometry>
            <mesh>
              <uri>model://youbot/meshes/arm/arm2.dae</uri>
              <scale>1 1 1</scale>
            </mesh>
          </geometry>
        </visual>
        <gravity>1</gravity>
        <self_collide>0</self_collide>
        <kinematic>0</kinematic>
      </link>
      <link name='arm_link_3'>
        <pose frame=''>0.272845 -0.018663 0.226506 -0 1.41372 2.96706</pose>
        <inertial>
          <pose frame=''>0.0001 0.0967 0.02107 0 -0 0</pose>
          <inertia>
            <ixx>0.002459</ixx>
            <ixy>0</ixy>
            <ixz>0</ixz>
            <iyy>0.002571</iyy>
            <iyz>-0</iyz>
            <izz>0.000535</izz>
          </inertia>
          <mass>0.934</mass>
        </inertial>
        <collision name='arm_link_3_geom'>
          <pose frame=''>0 0.028 0.079 0 -0 0</pose>
          <geometry>
            <mesh>
              <uri>model://youbot/meshes/arm/arm3_convex.stl</uri>
              <scale>1 1 1</scale>
            </mesh>
          </geometry>
          <surface>
            <friction>
              <ode>
                <mu>0</mu>
                <mu2>0</mu2>
                <fdir1>0 0 0</fdir1>
                <slip1>0</slip1>
                <slip2>0</slip2>
              </ode>
              <torsional>
                <ode/>
              </torsional>
            </friction>
            <bounce>
              <restitution_coefficient>0</restitution_coefficient>
              <threshold>0</threshold>
            </bounce>
            <contact>
              <ode>
                <soft_cfm>0</soft_cfm>
                <soft_erp>0.2</soft_erp>
                <kp>1e+13</kp>
                <kd>1e+11</kd>
                <max_vel>-1</max_vel>
                <min_depth>0</min_depth>
              </ode>
            </contact>
          </surface>
          <laser_retro>0</laser_retro>
          <max_contacts>10</max_contacts>
        </collision>
        <visual name='arm_link_3_geom_visual'>
          <pose frame=''>0 0.028 0.079 0 -0 0</pose>
          <geometry>
            <mesh>
              <uri>model://youbot/meshes/arm/arm3.dae</uri>
              <scale>1 1 1</scale>
            </mesh>
          </geometry>
        </visual>
        <gravity>1</gravity>
        <self_collide>0</self_collide>
        <kinematic>0</kinematic>
      </link>
      <link name='arm_link_4'>
        <pose frame=''>0.141533 0.004491 0.247624 0 -0.375246 2.96706</pose>
        <inertial>
          <pose frame=''>0.00011 0.05103 -0.02319 0 -0 0</pose>
          <inertia>
            <ixx>0.000869</ixx>
            <ixy>0</ixy>
            <ixz>-0</ixz>
            <iyy>0.001173</iyy>
            <iyz>-0.000231</iyz>
            <izz>0.001091</izz>
          </inertia>
          <mass>0.877</mass>
        </inertial>
        <collision name='arm_link_4_geom'>
          <pose frame=''>0 -0.01 0.029 0 -0 0</pose>
          <geometry>
            <mesh>
              <uri>model://youbot/meshes/arm/arm4_convex.stl</uri>
              <scale>1 1 1</scale>
            </mesh>
          </geometry>
          <surface>
            <friction>
              <ode>
                <mu>0</mu>
                <mu2>0</mu2>
                <fdir1>0 0 0</fdir1>
                <slip1>0</slip1>
                <slip2>0</slip2>
              </ode>
              <torsional>
                <ode/>
              </torsional>
            </friction>
            <bounce>
              <restitution_coefficient>0</restitution_coefficient>
              <threshold>0</threshold>
            </bounce>
            <contact>
              <ode>
                <soft_cfm>0</soft_cfm>
                <soft_erp>0.2</soft_erp>
                <kp>1e+13</kp>
                <kd>1e+11</kd>
                <max_vel>-1</max_vel>
                <min_depth>0</min_depth>
              </ode>
            </contact>
          </surface>
          <laser_retro>0</laser_retro>
          <max_contacts>10</max_contacts>
        </collision>
        <visual name='arm_link_4_geom_visual'>
          <pose frame=''>0 -0.01 0.029 0 -0 0</pose>
          <geometry>
            <mesh>
              <uri>model://youbot/meshes/arm/arm4.dae</uri>
              <scale>1 1 1</scale>
            </mesh>
          </geometry>
        </visual>
        <gravity>1</gravity>
        <self_collide>0</self_collide>
        <kinematic>0</kinematic>
      </link>
      <link name='arm_link_5'>
        <pose frame=''>0.190287 -0.004106 0.367846 -0.085052 0.365926 -0.408445</pose>
        <inertial>
          <pose frame=''>0 0.00115 -0.01683 0 -0 0</pose>
          <inertia>
            <ixx>0.00028</ixx>
            <ixy>0</ixy>
            <ixz>0</ixz>
            <iyy>0.000339</iyy>
            <iyz>0</iyz>
            <izz>0.000119</izz>
          </inertia>
          <mass>0.251</mass>
        </inertial>
        <collision name='arm_link_5_geom'>
          <pose frame=''>0.003 0 -0.034 0 -0 0</pose>
          <geometry>
            <mesh>
              <uri>model://youbot/meshes/arm/arm5_convex.stl</uri>
              <scale>1 1 1</scale>
            </mesh>
          </geometry>
          <surface>
            <friction>
              <ode>
                <mu>0</mu>
                <mu2>0</mu2>
                <fdir1>0 0 0</fdir1>
                <slip1>0</slip1>
                <slip2>0</slip2>
              </ode>
              <torsional>
                <ode/>
              </torsional>
            </friction>
            <bounce>
              <restitution_coefficient>0</restitution_coefficient>
              <threshold>0</threshold>
            </bounce>
            <contact>
              <ode>
                <soft_cfm>0</soft_cfm>
                <soft_erp>0.2</soft_erp>
                <kp>1e+13</kp>
                <kd>1e+11</kd>
                <max_vel>-1</max_vel>
                <min_depth>0</min_depth>
              </ode>
            </contact>
          </surface>
          <laser_retro>0</laser_retro>
          <max_contacts>10</max_contacts>
        </collision>
        <visual name='arm_link_5_geom_visual'>
          <pose frame=''>0.003 0 -0.034 0 -0 0</pose>
          <geometry>
            <mesh>
              <uri>model://youbot/meshes/arm/arm5.dae</uri>
              <scale>1 1 1</scale>
            </mesh>
          </geometry>
        </visual>
        <gravity>1</gravity>
        <self_collide>0</self_collide>
        <kinematic>0</kinematic>
      </link>
      <link name='gripper_palm_link'>
        <pose frame=''>0.190287 -0.004106 0.367846 -0.085052 0.365926 -0.408445</pose>
        <inertial>
          <pose frame=''>0 0 0 0 -0 0</pose>
          <inertia>
            <ixx>0.01</ixx>
            <ixy>0</ixy>
            <ixz>0</ixz>
            <iyy>0.01</iyy>
            <iyz>0</iyz>
            <izz>0.01</izz>
          </inertia>
          <mass>0.1</mass>
        </inertial>
        <collision name='gripper_palm_link_geom'>
          <pose frame=''>0 0 0 0 -0 0</pose>
          <geometry>
            <mesh>
              <uri>model://youbot/meshes/gripper/palm_convex.stl</uri>
              <scale>1 1 1</scale>
            </mesh>
          </geometry>
          <surface>
            <friction>
              <ode>
                <mu>0</mu>
                <mu2>0</mu2>
                <fdir1>0 0 0</fdir1>
                <slip1>0</slip1>
                <slip2>0</slip2>
              </ode>
              <torsional>
                <ode/>
              </torsional>
            </friction>
            <bounce>
              <restitution_coefficient>0</restitution_coefficient>
              <threshold>0</threshold>
            </bounce>
            <contact>
              <ode>
                <soft_cfm>0</soft_cfm>
                <soft_erp>0.2</soft_erp>
                <kp>1e+13</kp>
                <kd>1e+11</kd>
                <max_vel>-1</max_vel>
                <min_depth>0</min_depth>
              </ode>
            </contact>
          </surface>
          <laser_retro>0</laser_retro>
          <max_contacts>10</max_contacts>
        </collision>
        <visual name='gripper_palm_link_geom_visual'>
          <pose frame=''>0 0 0 0 -0 0</pose>
          <geometry>
            <mesh>
              <uri>model://youbot/meshes/gripper/palm.stl</uri>
              <scale>1 1 1</scale>
            </mesh>
          </geometry>
          <material>
            <script>
              <uri>file://media/materials/scripts/gazebo.material</uri>
              <name>Gazebo/Black</name>
            </script>
          </material>
        </visual>
        <gravity>1</gravity>
        <self_collide>1</self_collide>
        <kinematic>0</kinematic>
      </link>
      <link name='gripper_finger_link_l'>
        <pose frame=''>0.21326 -0.001105 0.408579 0.085052 -0.365926 2.73315</pose>
        <inertial>
          <pose frame=''>0 -0.001 0 0 -0 0</pose>
          <inertia>
            <ixx>0.01</ixx>
            <ixy>0</ixy>
            <ixz>0</ixz>
            <iyy>0.01</iyy>
            <iyz>0</iyz>
            <izz>0.01</izz>
          </inertia>
          <mass>0.01</mass>
        </inertial>
        <collision name='gripper_finger_link_l_geom'>
          <pose frame=''>0 0 0 0 -0 0</pose>
          <geometry>
            <mesh>
              <uri>model://youbot/meshes/gripper/finger_convex.stl</uri>
              <scale>1 1 1</scale>
            </mesh>
          </geometry>
          <surface>
            <friction>
              <ode>
                <mu>0</mu>
                <mu2>0</mu2>
                <fdir1>0 0 0</fdir1>
                <slip1>0</slip1>
                <slip2>0</slip2>
              </ode>
              <torsional>
                <ode/>
              </torsional>
            </friction>
            <bounce>
              <restitution_coefficient>0</restitution_coefficient>
              <threshold>0</threshold>
            </bounce>
            <contact>
              <ode>
                <soft_cfm>0</soft_cfm>
                <soft_erp>0.2</soft_erp>
                <kp>1e+13</kp>
                <kd>1e+11</kd>
                <max_vel>-1</max_vel>
                <min_depth>0</min_depth>
              </ode>
            </contact>
          </surface>
          <laser_retro>0</laser_retro>
          <max_contacts>10</max_contacts>
        </collision>
        <visual name='gripper_finger_link_l_geom_visual'>
          <pose frame=''>0 0 0 0 -0 0</pose>
          <geometry>
            <mesh>
              <uri>model://youbot/meshes/gripper/finger.stl</uri>
              <scale>1 1 1</scale>
            </mesh>
          </geometry>
        </visual>
        <gravity>1</gravity>
        <self_collide>0</self_collide>
        <kinematic>0</kinematic>
      </link>
      <link name='gripper_finger_link_r'>
        <pose frame=''>0.207375 -0.015929 0.409848 -0.085052 0.365926 -0.408445</pose>
        <inertial>
          <pose frame=''>0 -0.001 0 0 -0 0</pose>
          <inertia>
            <ixx>0.01</ixx>
            <ixy>0</ixy>
            <ixz>0</ixz>
            <iyy>0.01</iyy>
            <iyz>0</iyz>
            <izz>0.01</izz>
          </inertia>
          <mass>0.01</mass>
        </inertial>
        <collision name='gripper_finger_link_r_geom'>
          <pose frame=''>0 0 0 0 -0 0</pose>
          <geometry>
            <mesh>
              <uri>model://youbot/meshes/gripper/finger_convex.stl</uri>
              <scale>1 1 1</scale>
            </mesh>
          </geometry>
          <surface>
            <friction>
              <ode>
                <mu>0</mu>
                <mu2>0</mu2>
                <fdir1>0 0 0</fdir1>
                <slip1>0</slip1>
                <slip2>0</slip2>
              </ode>
              <torsional>
                <ode/>
              </torsional>
            </friction>
            <bounce>
              <restitution_coefficient>0</restitution_coefficient>
              <threshold>0</threshold>
            </bounce>
            <contact>
              <ode>
                <soft_cfm>0</soft_cfm>
                <soft_erp>0.2</soft_erp>
                <kp>1e+13</kp>
                <kd>1e+11</kd>
                <max_vel>-1</max_vel>
                <min_depth>0</min_depth>
              </ode>
            </contact>
          </surface>
          <laser_retro>0</laser_retro>
          <max_contacts>10</max_contacts>
        </collision>
        <visual name='gripper_finger_link_r_geom_visual'>
          <pose frame=''>0 0 0 0 -0 0</pose>
          <geometry>
            <mesh>
              <uri>model://youbot/meshes/gripper/finger.stl</uri>
              <scale>1 1 1</scale>
            </mesh>
          </geometry>
        </visual>
        <gravity>1</gravity>
        <self_collide>0</self_collide>
        <kinematic>0</kinematic>
      </link>
      <link name='base_laser_front_link'>
        <pose frame=''>0.3 0 -0.03 0 -0 0</pose>
        <inertial>
          <pose frame=''>0 0 0 0 -0 0</pose>
          <inertia>
            <ixx>0.1</ixx>
            <ixy>0</ixy>
            <ixz>0</ixz>
            <iyy>0.1</iyy>
            <iyz>0</iyz>
            <izz>0.1</izz>
          </inertia>
          <mass>0.16</mass>
        </inertial>
        <collision name='base_laser_front_link_geom'>
          <pose frame=''>0 0 0 0 -0 0</pose>
          <geometry>
            <mesh>
              <uri>model://hokuyo/meshes/hokuyo_convex.stl</uri>
              <scale>1 1 1</scale>
            </mesh>
          </geometry>
          <surface>
            <friction>
              <ode>
                <mu>0</mu>
                <mu2>0</mu2>
                <fdir1>0 0 0</fdir1>
                <slip1>0</slip1>
                <slip2>0</slip2>
              </ode>
              <torsional>
                <ode/>
              </torsional>
            </friction>
            <bounce>
              <restitution_coefficient>0</restitution_coefficient>
              <threshold>0</threshold>
            </bounce>
            <contact>
              <ode>
                <soft_cfm>0</soft_cfm>
                <soft_erp>0.2</soft_erp>
                <kp>1e+13</kp>
                <kd>1e+11</kd>
                <max_vel>-1</max_vel>
                <min_depth>0</min_depth>
              </ode>
            </contact>
          </surface>
          <laser_retro>0</laser_retro>
          <max_contacts>10</max_contacts>
        </collision>
        <visual name='base_laser_front_link_geom_visual'>
          <pose frame=''>0 0 0 0 -0 0</pose>
          <geometry>
            <mesh>
              <uri>model://hokuyo/meshes/hokuyo.dae</uri>
              <scale>1 1 1</scale>
            </mesh>
          </geometry>
        </visual>
        <sensor name='base_laser_front' type='ray'>
          <pose frame=''>0 0 0 0 -0 0</pose>
          <ray>
            <scan>
              <horizontal>
                <samples>640</samples>
                <resolution>1</resolution>
                <min_angle>-1.57</min_angle>
                <max_angle>1.57</max_angle>
              </horizontal>
              <vertical>
                <samples>1</samples>
                <min_angle>0</min_angle>
                <max_angle>0</max_angle>
              </vertical>
            </scan>
            <range>
              <min>0.05</min>
              <max>5.6</max>
              <resolution>0.36</resolution>
            </range>
          </ray>
          <always_on>0</always_on>
          <update_rate>10</update_rate>
          <visualize>0</visualize>
        </sensor>
        <gravity>1</gravity>
        <self_collide>0</self_collide>
        <kinematic>0</kinematic>
      </link>
      <link name='caster_link_bl'>
        <pose frame=''>-0.228 0.158 -0.034 0 -0 0</pose>
        <inertial>
          <pose frame=''>0 0 0 0 -0 0</pose>
          <inertia>
            <ixx>0.012412</ixx>
            <ixy>-0.000712</ixy>
            <ixz>0.000503</ixz>
            <iyy>0.015218</iyy>
            <iyz>-4e-06</iyz>
            <izz>0.011764</izz>
          </inertia>
          <mass>0.1</mass>
        </inertial>
        <gravity>1</gravity>
        <self_collide>0</self_collide>
        <kinematic>0</kinematic>
      </link>
      <link name='wheel_link_bl'>
        <pose frame=''>-0.228 0.158 -0.034 0 -0 0</pose>
        <inertial>
          <pose frame=''>0 0 0 0 -0 0</pose>
          <inertia>
            <ixx>0.012412</ixx>
            <ixy>-0.000712</ixy>
            <ixz>0.000503</ixz>
            <iyy>0.015218</iyy>
            <iyz>-4e-06</iyz>
            <izz>0.011764</izz>
          </inertia>
          <mass>0.4</mass>
        </inertial>
        <collision name='wheel_link_bl_geom'>
          <pose frame=''>0 0 0 1.5708 -0 0</pose>
          <geometry>
            <cylinder>
              <radius>0.05</radius>
              <length>0.005</length>
            </cylinder>
          </geometry>
          <surface>
            <friction>
              <ode>
                <mu>0</mu>
                <mu2>0</mu2>
                <fdir1>0 0 0</fdir1>
                <slip1>0</slip1>
                <slip2>0</slip2>
              </ode>
              <torsional>
                <ode/>
              </torsional>
            </friction>
            <bounce>
              <restitution_coefficient>0</restitution_coefficient>
              <threshold>0</threshold>
            </bounce>
            <contact>
              <ode>
                <soft_cfm>0</soft_cfm>
                <soft_erp>0.2</soft_erp>
                <kp>1e+13</kp>
                <kd>1e+11</kd>
                <max_vel>-1</max_vel>
                <min_depth>0</min_depth>
              </ode>
            </contact>
          </surface>
          <laser_retro>0</laser_retro>
          <max_contacts>10</max_contacts>
        </collision>
        <visual name='wheel_link_bl_geom_visual'>
          <pose frame=''>0 0 0 0 -0 0</pose>
          <geometry>
            <mesh>
              <uri>model://youbot/meshes/base/back-left_wheel.dae</uri>
              <scale>1 1 1</scale>
            </mesh>
          </geometry>
          <material>
            <script>
              <uri>model://youbot/materials/scripts/youbot.material</uri>
              <name>youbot/Orange</name>
            </script>
          </material>
        </visual>
        <gravity>1</gravity>
        <self_collide>0</self_collide>
        <kinematic>0</kinematic>
      </link>
      <link name='caster_link_br'>
        <pose frame=''>-0.228 -0.158 -0.034 0 -0 0</pose>
        <inertial>
          <pose frame=''>0 0 0 0 -0 0</pose>
          <inertia>
            <ixx>0.012412</ixx>
            <ixy>-0.000712</ixy>
            <ixz>0.000503</ixz>
            <iyy>0.015218</iyy>
            <iyz>-4e-06</iyz>
            <izz>0.011764</izz>
          </inertia>
          <mass>0.1</mass>
        </inertial>
        <gravity>1</gravity>
        <self_collide>0</self_collide>
        <kinematic>0</kinematic>
      </link>
      <link name='wheel_link_br'>
        <pose frame=''>-0.228 -0.158 -0.034 0 -0 0</pose>
        <inertial>
          <pose frame=''>0 0 0 0 -0 0</pose>
          <inertia>
            <ixx>0.012412</ixx>
            <ixy>-0.000712</ixy>
            <ixz>0.000503</ixz>
            <iyy>0.015218</iyy>
            <iyz>-4e-06</iyz>
            <izz>0.011764</izz>
          </inertia>
          <mass>0.4</mass>
        </inertial>
        <collision name='wheel_link_br_geom'>
          <pose frame=''>0 0 0 1.5708 -0 0</pose>
          <geometry>
            <cylinder>
              <radius>0.05</radius>
              <length>0.005</length>
            </cylinder>
          </geometry>
          <surface>
            <friction>
              <ode>
                <mu>0</mu>
                <mu2>0</mu2>
                <fdir1>0 0 0</fdir1>
                <slip1>0</slip1>
                <slip2>0</slip2>
              </ode>
              <torsional>
                <ode/>
              </torsional>
            </friction>
            <bounce>
              <restitution_coefficient>0</restitution_coefficient>
              <threshold>0</threshold>
            </bounce>
            <contact>
              <ode>
                <soft_cfm>0</soft_cfm>
                <soft_erp>0.2</soft_erp>
                <kp>1e+13</kp>
                <kd>1e+11</kd>
                <max_vel>-1</max_vel>
                <min_depth>0</min_depth>
              </ode>
            </contact>
          </surface>
          <laser_retro>0</laser_retro>
          <max_contacts>10</max_contacts>
        </collision>
        <visual name='wheel_link_br_geom_visual'>
          <pose frame=''>0 0 0 0 -0 0</pose>
          <geometry>
            <mesh>
              <uri>model://youbot/meshes/base/back-right_wheel.dae</uri>
              <scale>1 1 1</scale>
            </mesh>
          </geometry>
          <material>
            <script>
              <uri>model://youbot/materials/scripts/youbot.material</uri>
              <name>youbot/Orange</name>
            </script>
          </material>
        </visual>
        <gravity>1</gravity>
        <self_collide>0</self_collide>
        <kinematic>0</kinematic>
      </link>
      <link name='caster_link_fl'>
        <pose frame=''>0.228 0.158 -0.034 0 -0 0</pose>
        <inertial>
          <pose frame=''>0 0 0 0 -0 0</pose>
          <inertia>
            <ixx>0.012412</ixx>
            <ixy>-0.000712</ixy>
            <ixz>0.000503</ixz>
            <iyy>0.015218</iyy>
            <iyz>-4e-06</iyz>
            <izz>0.011764</izz>
          </inertia>
          <mass>0.1</mass>
        </inertial>
        <gravity>1</gravity>
        <self_collide>0</self_collide>
        <kinematic>0</kinematic>
      </link>
      <link name='wheel_link_fl'>
        <pose frame=''>0.228 0.158 -0.034 0 -0 0</pose>
        <inertial>
          <pose frame=''>0 0 0 0 -0 0</pose>
          <inertia>
            <ixx>0.012412</ixx>
            <ixy>-0.000712</ixy>
            <ixz>0.000503</ixz>
            <iyy>0.015218</iyy>
            <iyz>-4e-06</iyz>
            <izz>0.011764</izz>
          </inertia>
          <mass>0.4</mass>
        </inertial>
        <collision name='wheel_link_fl_geom'>
          <pose frame=''>0 0 0 1.5708 -0 0</pose>
          <geometry>
            <cylinder>
              <radius>0.05</radius>
              <length>0.005</length>
            </cylinder>
          </geometry>
          <surface>
            <friction>
              <ode>
                <mu>0</mu>
                <mu2>0</mu2>
                <fdir1>0 0 0</fdir1>
                <slip1>0</slip1>
                <slip2>0</slip2>
              </ode>
              <torsional>
                <ode/>
              </torsional>
            </friction>
            <bounce>
              <restitution_coefficient>0</restitution_coefficient>
              <threshold>0</threshold>
            </bounce>
            <contact>
              <ode>
                <soft_cfm>0</soft_cfm>
                <soft_erp>0.2</soft_erp>
                <kp>1e+13</kp>
                <kd>1e+11</kd>
                <max_vel>-1</max_vel>
                <min_depth>0</min_depth>
              </ode>
            </contact>
          </surface>
          <laser_retro>0</laser_retro>
          <max_contacts>10</max_contacts>
        </collision>
        <visual name='wheel_link_fl_geom_visual'>
          <pose frame=''>0 0 0 0 -0 0</pose>
          <geometry>
            <mesh>
              <uri>model://youbot/meshes/base/front-left_wheel.dae</uri>
              <scale>1 1 1</scale>
            </mesh>
          </geometry>
          <material>
            <script>
              <uri>model://youbot/materials/scripts/youbot.material</uri>
              <name>youbot/Orange</name>
            </script>
          </material>
        </visual>
        <gravity>1</gravity>
        <self_collide>0</self_collide>
        <kinematic>0</kinematic>
      </link>
      <link name='caster_link_fr'>
        <pose frame=''>0.228 -0.158 -0.034 0 -0 0</pose>
        <inertial>
          <pose frame=''>0 0 0 0 -0 0</pose>
          <inertia>
            <ixx>0.012412</ixx>
            <ixy>-0.000712</ixy>
            <ixz>0.000503</ixz>
            <iyy>0.015218</iyy>
            <iyz>-4e-06</iyz>
            <izz>0.011764</izz>
          </inertia>
          <mass>0.1</mass>
        </inertial>
        <gravity>1</gravity>
        <self_collide>0</self_collide>
        <kinematic>0</kinematic>
      </link>
      <link name='wheel_link_fr'>
        <pose frame=''>0.228 -0.158 -0.034 0 -0 0</pose>
        <inertial>
          <pose frame=''>0 0 0 0 -0 0</pose>
          <inertia>
            <ixx>0.012412</ixx>
            <ixy>-0.000712</ixy>
            <ixz>0.000503</ixz>
            <iyy>0.015218</iyy>
            <iyz>-4e-06</iyz>
            <izz>0.011764</izz>
          </inertia>
          <mass>0.4</mass>
        </inertial>
        <collision name='wheel_link_fr_geom'>
          <pose frame=''>0 0 0 1.5708 -0 0</pose>
          <geometry>
            <cylinder>
              <radius>0.05</radius>
              <length>0.005</length>
            </cylinder>
          </geometry>
          <surface>
            <friction>
              <ode>
                <mu>0</mu>
                <mu2>0</mu2>
                <fdir1>0 0 0</fdir1>
                <slip1>0</slip1>
                <slip2>0</slip2>
              </ode>
              <torsional>
                <ode/>
              </torsional>
            </friction>
            <bounce>
              <restitution_coefficient>0</restitution_coefficient>
              <threshold>0</threshold>
            </bounce>
            <contact>
              <ode>
                <soft_cfm>0</soft_cfm>
                <soft_erp>0.2</soft_erp>
                <kp>1e+13</kp>
                <kd>1e+11</kd>
                <max_vel>-1</max_vel>
                <min_depth>0</min_depth>
              </ode>
            </contact>
          </surface>
          <laser_retro>0</laser_retro>
          <max_contacts>10</max_contacts>
        </collision>
        <visual name='wheel_link_fr_geom_visual'>
          <pose frame=''>0 0 0 0 -0 0</pose>
          <geometry>
            <mesh>
              <uri>model://youbot/meshes/base/front-right_wheel.dae</uri>
              <scale>1 1 1</scale>
            </mesh>
          </geometry>
          <material>
            <script>
              <uri>model://youbot/materials/scripts/youbot.material</uri>
              <name>youbot/Orange</name>
            </script>
          </material>
        </visual>
        <gravity>1</gravity>
        <self_collide>0</self_collide>
        <kinematic>0</kinematic>
      </link>
      <link name='plate_link'>
        <pose frame=''>-0.159 0 0.046 0 -0 0</pose>
        <inertial>
          <pose frame=''>0 0 0 0 -0 0</pose>
          <inertia>
            <ixx>0.01</ixx>
            <ixy>0</ixy>
            <ixz>0</ixz>
            <iyy>0.01</iyy>
            <iyz>0</iyz>
            <izz>0.01</izz>
          </inertia>
          <mass>1</mass>
        </inertial>
        <collision name='plate_link_geom'>
          <pose frame=''>0 0 0 0 -0 0</pose>
          <geometry>
            <mesh>
              <uri>model://youbot/meshes/plate/plate_convex.stl</uri>
              <scale>1 1 1</scale>
            </mesh>
          </geometry>
          <surface>
            <friction>
              <ode>
                <mu>0</mu>
                <mu2>0</mu2>
                <fdir1>0 0 0</fdir1>
                <slip1>0</slip1>
                <slip2>0</slip2>
              </ode>
              <torsional>
                <ode/>
              </torsional>
            </friction>
            <bounce>
              <restitution_coefficient>0</restitution_coefficient>
              <threshold>0</threshold>
            </bounce>
            <contact>
              <ode>
                <soft_cfm>0</soft_cfm>
                <soft_erp>0.2</soft_erp>
                <kp>1e+13</kp>
                <kd>1e+11</kd>
                <max_vel>-1</max_vel>
                <min_depth>0</min_depth>
              </ode>
            </contact>
          </surface>
          <laser_retro>0</laser_retro>
          <max_contacts>10</max_contacts>
        </collision>
        <visual name='plate_link_geom_visual'>
          <pose frame=''>0 0 0 0 -0 0</pose>
          <geometry>
            <mesh>
              <uri>model://youbot/meshes/plate/plate.dae</uri>
              <scale>1 1 1</scale>
            </mesh>
          </geometry>
        </visual>
        <gravity>1</gravity>
        <self_collide>0</self_collide>
        <kinematic>0</kinematic>
      </link>
      <joint name='base_footprint_joint' type='revolute'>
        <pose frame=''>0 0 0 0 -0 0</pose>
        <parent>base_footprint</parent>
        <child>base_link</child>
        <axis>
          <dynamics>
            <damping>0</damping>
            <friction>0</friction>
            <spring_reference>0</spring_reference>
            <spring_stiffness>0</spring_stiffness>
          </dynamics>
          <limit>
            <lower>0</lower>
            <upper>0</upper>
            <effort>0</effort>
            <velocity>0</velocity>
          </limit>
          <xyz>0 0 1</xyz>
          <use_parent_model_frame>1</use_parent_model_frame>
        </axis>
      </joint>
      <joint name='arm_joint_0' type='revolute'>
        <pose frame=''>0 0 0 0 -0 0</pose>
        <parent>base_link</parent>
        <child>arm_link_0</child>
        <axis>
          <dynamics>
            <damping>0</damping>
            <friction>0</friction>
            <spring_reference>0</spring_reference>
            <spring_stiffness>0</spring_stiffness>
          </dynamics>
          <limit>
            <lower>0</lower>
            <upper>0</upper>
            <effort>0</effort>
            <velocity>0</velocity>
          </limit>
          <xyz>0 0 1</xyz>
          <use_parent_model_frame>1</use_parent_model_frame>
        </axis>
      </joint>
      <joint name='arm_joint_1' type='revolute'>
        <pose frame=''>0 0 0 0 -0 0</pose>
        <parent>arm_link_0</parent>
        <child>arm_link_1</child>
        <axis>
          <dynamics>
            <damping>1</damping>
            <friction>0</friction>
            <spring_reference>0</spring_reference>
            <spring_stiffness>0</spring_stiffness>
          </dynamics>
          <limit>
            <lower>0</lower>
            <upper>5.89921</upper>
            <effort>0</effort>
            <velocity>0</velocity>
          </limit>
          <xyz>0 0 -1</xyz>
          <use_parent_model_frame>1</use_parent_model_frame>
        </axis>
      </joint>
      <joint name='arm_joint_2' type='revolute'>
        <pose frame=''>0 0 0 0 -0 0</pose>
        <parent>arm_link_1</parent>
        <child>arm_link_2</child>
        <axis>
          <dynamics>
            <damping>1</damping>
            <friction>0</friction>
            <spring_reference>0</spring_reference>
            <spring_stiffness>0</spring_stiffness>
          </dynamics>
          <limit>
            <lower>0</lower>
            <upper>2.70526</upper>
            <effort>0</effort>
            <velocity>0</velocity>
          </limit>
          <xyz>-0.173648 -0.984808 0</xyz>
          <use_parent_model_frame>1</use_parent_model_frame>
        </axis>
      </joint>
      <joint name='arm_joint_3' type='revolute'>
        <pose frame=''>0 0 0 0 -0 0</pose>
        <parent>arm_link_2</parent>
        <child>arm_link_3</child>
        <axis>
          <dynamics>
            <damping>1</damping>
            <friction>0</friction>
            <spring_reference>0</spring_reference>
            <spring_stiffness>0</spring_stiffness>
          </dynamics>
          <limit>
            <lower>-5.18363</lower>
            <upper>0</upper>
            <effort>0</effort>
            <velocity>0</velocity>
          </limit>
          <xyz>-0.173648 -0.984808 0</xyz>
          <use_parent_model_frame>1</use_parent_model_frame>
        </axis>
      </joint>
      <joint name='arm_joint_4' type='revolute'>
        <pose frame=''>0 0 0 0 -0 0</pose>
        <parent>arm_link_3</parent>
        <child>arm_link_4</child>
        <axis>
          <dynamics>
            <damping>1</damping>
            <friction>0</friction>
            <spring_reference>0</spring_reference>
            <spring_stiffness>0</spring_stiffness>
          </dynamics>
          <limit>
            <lower>0</lower>
            <upper>3.57793</upper>
            <effort>0</effort>
            <velocity>0</velocity>
          </limit>
          <xyz>-0.173648 -0.984808 0</xyz>
          <use_parent_model_frame>1</use_parent_model_frame>
        </axis>
      </joint>
      <joint name='arm_joint_5' type='revolute'>
        <pose frame=''>0 0 0 0 -0 0</pose>
        <parent>arm_link_4</parent>
        <child>arm_link_5</child>
        <axis>
          <dynamics>
            <damping>1</damping>
            <friction>0</friction>
            <spring_reference>0</spring_reference>
            <spring_stiffness>0</spring_stiffness>
          </dynamics>
          <limit>
            <lower>0</lower>
            <upper>5.84685</upper>
            <effort>0</effort>
            <velocity>0</velocity>
          </limit>
          <xyz>-0.360933 0.063642 -0.930418</xyz>
          <use_parent_model_frame>1</use_parent_model_frame>
        </axis>
      </joint>
      <joint name='gripper_palm_joint' type='revolute'>
        <pose frame=''>0 0 0 0 -0 0</pose>
        <parent>arm_link_5</parent>
        <child>gripper_palm_link</child>
        <axis>
          <dynamics>
            <damping>0</damping>
            <friction>0</friction>
            <spring_reference>0</spring_reference>
            <spring_stiffness>0</spring_stiffness>
          </dynamics>
          <limit>
            <lower>0</lower>
            <upper>0</upper>
            <effort>0</effort>
            <velocity>0</velocity>
          </limit>
          <xyz>0 0 1</xyz>
          <use_parent_model_frame>1</use_parent_model_frame>
        </axis>
      </joint>
      <joint name='gripper_finger_joint_l' type='prismatic'>
        <pose frame=''>0 0 0 0 -0 0</pose>
        <parent>gripper_palm_link</parent>
        <child>gripper_finger_link_l</child>
        <axis>
          <dynamics>
            <damping>1</damping>
            <friction>0</friction>
            <spring_reference>0</spring_reference>
            <spring_stiffness>0</spring_stiffness>
          </dynamics>
          <limit>
            <lower>0</lower>
            <upper>0.0115</upper>
            <effort>0</effort>
            <velocity>0</velocity>
          </limit>
          <xyz>0.367852 0.926495 -0.079325</xyz>
          <use_parent_model_frame>1</use_parent_model_frame>
        </axis>
      </joint>
      <joint name='gripper_finger_joint_r' type='prismatic'>
        <pose frame=''>0 0 0 0 -0 0</pose>
        <parent>gripper_palm_link</parent>
        <child>gripper_finger_link_r</child>
        <axis>
          <dynamics>
            <damping>1</damping>
            <friction>0</friction>
            <spring_reference>0</spring_reference>
            <spring_stiffness>0</spring_stiffness>
          </dynamics>
          <limit>
            <lower>0</lower>
            <upper>0.0115</upper>
            <effort>0</effort>
            <velocity>0</velocity>
          </limit>
          <xyz>-0.367852 -0.926495 0.079325</xyz>
          <use_parent_model_frame>1</use_parent_model_frame>
        </axis>
      </joint>
      <joint name='base_laser_front_hokuyo_urg04_laser_joint' type='revolute'>
        <pose frame=''>0 0 0 0 -0 0</pose>
        <parent>base_link</parent>
        <child>base_laser_front_link</child>
        <axis>
          <dynamics>
            <damping>0</damping>
            <friction>0</friction>
            <spring_reference>0</spring_reference>
            <spring_stiffness>0</spring_stiffness>
          </dynamics>
          <limit>
            <lower>0</lower>
            <upper>0</upper>
            <effort>0</effort>
            <velocity>0</velocity>
          </limit>
          <xyz>0 0 1</xyz>
          <use_parent_model_frame>1</use_parent_model_frame>
        </axis>
      </joint>
      <joint name='caster_joint_bl' type='revolute'>
        <pose frame=''>0 0 0 0 -0 0</pose>
        <parent>base_link</parent>
        <child>caster_link_bl</child>
        <axis>
          <dynamics>
            <damping>1</damping>
            <friction>0</friction>
            <spring_reference>0</spring_reference>
            <spring_stiffness>0</spring_stiffness>
          </dynamics>
          <limit>
            <lower>-1e+16</lower>
            <upper>1e+16</upper>
            <effort>0</effort>
            <velocity>0</velocity>
          </limit>
          <xyz>0 0 1</xyz>
          <use_parent_model_frame>1</use_parent_model_frame>
        </axis>
      </joint>
      <joint name='wheel_joint_bl' type='revolute'>
        <pose frame=''>0 0 0 0 -0 0</pose>
        <parent>caster_link_bl</parent>
        <child>wheel_link_bl</child>
        <axis>
          <dynamics>
            <damping>1</damping>
            <friction>0</friction>
            <spring_reference>0</spring_reference>
            <spring_stiffness>0</spring_stiffness>
          </dynamics>
          <limit>
            <lower>-1e+16</lower>
            <upper>1e+16</upper>
            <effort>0</effort>
            <velocity>0</velocity>
          </limit>
          <xyz>0 1 0</xyz>
          <use_parent_model_frame>1</use_parent_model_frame>
        </axis>
      </joint>
      <joint name='caster_joint_br' type='revolute'>
        <pose frame=''>0 0 0 0 -0 0</pose>
        <parent>base_link</parent>
        <child>caster_link_br</child>
        <axis>
          <dynamics>
            <damping>1</damping>
            <friction>0</friction>
            <spring_reference>0</spring_reference>
            <spring_stiffness>0</spring_stiffness>
          </dynamics>
          <limit>
            <lower>-1e+16</lower>
            <upper>1e+16</upper>
            <effort>0</effort>
            <velocity>0</velocity>
          </limit>
          <xyz>0 0 1</xyz>
          <use_parent_model_frame>1</use_parent_model_frame>
        </axis>
      </joint>
      <joint name='wheel_joint_br' type='revolute'>
        <pose frame=''>0 0 0 0 -0 0</pose>
        <parent>caster_link_br</parent>
        <child>wheel_link_br</child>
        <axis>
          <dynamics>
            <damping>1</damping>
            <friction>0</friction>
            <spring_reference>0</spring_reference>
            <spring_stiffness>0</spring_stiffness>
          </dynamics>
          <limit>
            <lower>-1e+16</lower>
            <upper>1e+16</upper>
            <effort>0</effort>
            <velocity>0</velocity>
          </limit>
          <xyz>0 1 0</xyz>
          <use_parent_model_frame>1</use_parent_model_frame>
        </axis>
      </joint>
      <joint name='caster_joint_fl' type='revolute'>
        <pose frame=''>0 0 0 0 -0 0</pose>
        <parent>base_link</parent>
        <child>caster_link_fl</child>
        <axis>
          <dynamics>
            <damping>1</damping>
            <friction>0</friction>
            <spring_reference>0</spring_reference>
            <spring_stiffness>0</spring_stiffness>
          </dynamics>
          <limit>
            <lower>-1e+16</lower>
            <upper>1e+16</upper>
            <effort>0</effort>
            <velocity>0</velocity>
          </limit>
          <xyz>0 0 1</xyz>
          <use_parent_model_frame>1</use_parent_model_frame>
        </axis>
      </joint>
      <joint name='wheel_joint_fl' type='revolute'>
        <pose frame=''>0 0 0 0 -0 0</pose>
        <parent>caster_link_fl</parent>
        <child>wheel_link_fl</child>
        <axis>
          <dynamics>
            <damping>1</damping>
            <friction>0</friction>
            <spring_reference>0</spring_reference>
            <spring_stiffness>0</spring_stiffness>
          </dynamics>
          <limit>
            <lower>-1e+16</lower>
            <upper>1e+16</upper>
            <effort>0</effort>
            <velocity>0</velocity>
          </limit>
          <xyz>0 1 0</xyz>
          <use_parent_model_frame>1</use_parent_model_frame>
        </axis>
      </joint>
      <joint name='caster_joint_fr' type='revolute'>
        <pose frame=''>0 0 0 0 -0 0</pose>
        <parent>base_link</parent>
        <child>caster_link_fr</child>
        <axis>
          <dynamics>
            <damping>1</damping>
            <friction>0</friction>
            <spring_reference>0</spring_reference>
            <spring_stiffness>0</spring_stiffness>
          </dynamics>
          <limit>
            <lower>-1e+16</lower>
            <upper>1e+16</upper>
            <effort>0</effort>
            <velocity>0</velocity>
          </limit>
          <xyz>0 0 1</xyz>
          <use_parent_model_frame>1</use_parent_model_frame>
        </axis>
      </joint>
      <joint name='wheel_joint_fr' type='revolute'>
        <pose frame=''>0 0 0 0 -0 0</pose>
        <parent>caster_link_fr</parent>
        <child>wheel_link_fr</child>
        <axis>
          <dynamics>
            <damping>1</damping>
            <friction>0</friction>
            <spring_reference>0</spring_reference>
            <spring_stiffness>0</spring_stiffness>
          </dynamics>
          <limit>
            <lower>-1e+16</lower>
            <upper>1e+16</upper>
            <effort>0</effort>
            <velocity>0</velocity>
          </limit>
          <xyz>0 1 0</xyz>
          <use_parent_model_frame>1</use_parent_model_frame>
        </axis>
      </joint>
      <joint name='plate_joint' type='revolute'>
        <parent>base_link</parent>
        <child>plate_link</child>
        <axis>
          <dynamics>
            <damping>0</damping>
            <friction>0</friction>
            <spring_reference>0</spring_reference>
            <spring_stiffness>0</spring_stiffness>
          </dynamics>
          <limit>
            <lower>0</lower>
            <upper>0</upper>
            <effort>0</effort>
            <velocity>0</velocity>
          </limit>
          <xyz>0 0 1</xyz>
          <use_parent_model_frame>1</use_parent_model_frame>
        </axis>
      </joint>
      <static>0</static>
    </model>
    <model name='warehouse_robot'>
      <static>1</static>
      <link name='link'>
        <visual name='visual'>
          <geometry>
            <mesh>
              <uri>model://warehouse_robot/meshes/robot.dae</uri>
              <scale>1 1 1</scale>
            </mesh>
          </geometry>
        </visual>
        <collision name='collision_base'>
          <pose frame=''>0 0 0.20437 0 -0 0</pose>
          <geometry>
            <box>
              <size>0.55508 1.0228 0.40874</size>
            </box>
          </geometry>
          <max_contacts>10</max_contacts>
          <surface>
            <contact>
              <ode/>
            </contact>
            <bounce/>
            <friction>
              <torsional>
                <ode/>
              </torsional>
              <ode/>
            </friction>
          </surface>
        </collision>
        <collision name='collision_bumper'>
          <pose frame=''>0 0 0.062205 0 -0 0</pose>
          <geometry>
            <box>
              <size>0.67266 1.17126 0.12441</size>
            </box>
          </geometry>
          <max_contacts>10</max_contacts>
          <surface>
            <contact>
              <ode/>
            </contact>
            <bounce/>
            <friction>
              <torsional>
                <ode/>
              </torsional>
              <ode/>
            </friction>
          </surface>
        </collision>
        <collision name='collision_column_large'>
          <pose frame=''>0 -0.27539 0.43738 0 -0 0</pose>
          <geometry>
            <cylinder>
              <radius>0.08652</radius>
              <length>0.87476</length>
            </cylinder>
          </geometry>
          <max_contacts>10</max_contacts>
          <surface>
            <contact>
              <ode/>
            </contact>
            <bounce/>
            <friction>
              <torsional>
                <ode/>
              </torsional>
              <ode/>
            </friction>
          </surface>
        </collision>
        <collision name='collision_column_small'>
          <pose frame=''>0 -0.27539 0.70424 0 -0 0</pose>
          <geometry>
            <cylinder>
              <radius>0.04261</radius>
              <length>1.40848</length>
            </cylinder>
          </geometry>
          <max_contacts>10</max_contacts>
          <surface>
            <contact>
              <ode/>
            </contact>
            <bounce/>
            <friction>
              <torsional>
                <ode/>
              </torsional>
              <ode/>
            </friction>
          </surface>
        </collision>
        <self_collide>0</self_collide>
        <kinematic>0</kinematic>
        <gravity>1</gravity>
      </link>
      <pose frame=''>-0.961337 -6.5405 0 0 -0 0</pose>
    </model>
  </world>
</sdf>
